Workbook

Sheet 📋 Thông Tin
A1: ✦ JULES STUDIO
A2: Thiết kế Website — Trải nghiệm tạo nên giá trị
A3: 📧 duynt.7896@gmail.com • 📱 094 982 0369 • 🌐 julesstudio.pages.dev
A5: 📋 THÔNG TIN KHÁCH HÀNG
A6: Ngày báo giá: | C6: Hiệu lực: | D6: 30 ngày
A7: Khách hàng: | C7: Điện thoại:
A8: Email: | C8: Zalo:
A9: Tên website: | C9: Tên miền:
A10: Loại website: | C10: Gói:
A12: 🎨 PHONG CÁCH THIẾT KẾ (chọn 1-2)
A13: STT | B13: Phong cách | C13: Chọn | D13: Mô tả
A14: 1 | B14: Minimalism (Tối giản) | D14: Sạch, nhiều khoảng trống, tập trung nội dung
A15: 2 | B15: Exaggerated Minimalism | D15: Tối giản mạnh mẽ, chữ to, contrast cao
A16: 3 | B16: Glassmorphism (Kính mờ) | D16: Hiệu ứng kính mờ, backdrop blur, trong suốt
A17: 4 | B17: Neumorphism (Soft UI) | D17: Nổi/lõm nhẹ, pastel, mềm mại
A18: 5 | B18: Neubrutalism | D18: Viền đen đậm, shadow cứng, màu sáng, Gen Z
A19: 6 | B19: Flat Design | D19: 2D, không shadow, màu sắc tươi sáng
A20: 7 | B20: Dark Mode (OLED) | D20: Nền đen, chữ sáng, tiết kiệm pin OLED
A21: 8 | B21: Bento Box Grid | D21: Lưới module kiểu Apple, thẻ bo tròn
A22: 9 | B22: Aurora UI | D22: Gradient mượt kiểu cực quang, mesh gradient
A23: 10 | B23: Vibrant & Block-based | D23: Màu neon, block layout, năng động
A24: 11 | B24: Claymorphism | D24: 3D mềm, kiểu đồ chơi, playful
A25: 12 | B25: Motion-Driven | D25: Animation nhiều, scroll effects, parallax
... A36: 23 | B36: Storytelling-Driven | D36: Layout kể chuyện, scroll narrative
A37: 24 | B37: Khác (ghi bên ghi chú)
A39: 📝 YÊU CẦU THIẾT KẾ CHI TIẾT
A40: Màu sắc yêu thích: | B40: VD: xanh navy, vàng gold, trắng...
A41: Font chữ yêu thích: | B41: VD: Montserrat, Playfair Display, Be Vietnam Pro...
A42: Website tham khảo: | B42: Ghi URL website mẫu bạn thích
A43: Tone & Mood: | B43: VD: sang trọng, trẻ trung, chuyên nghiệp, vui tươi...
A44: Logo / Brand guidelines: | B44: Có sẵn logo? Có bộ nhận diện thương hiệu?
A45: Yêu cầu khác:
A47: 📝 GHI CHÚ & ĐIỀU KHOẢN
A48: 1. Báo giá có hiệu lực 30 ngày kể từ ngày lập.
A49: 2. Đặt cọc 40% trước khi bắt đầu. Thanh toán 60% còn lại khi nghiệm thu.
A50: 3. Thời gian tính từ ngày nhận đủ nội dung & tài liệu từ khách hàng.
A51: 4. Nội dung (text, hình ảnh) do khách hàng cung cấp. Hỗ trợ thiết kế banner miễn phí.
A52: 5. Sửa đổi lớn sau khi duyệt thiết kế sẽ phát sinh thêm phí.
A53: 6. Bảo trì miễn phí 1 tháng đầu (fix bug, cập nhật nội dung nhỏ).
A56: ĐẠI DIỆN JULES STUDIO | C56: KHÁCH HÀNG
...

Sheet 📊 Bảng Giá
A1: 📊 BẢNG GIÁ THAM KHẢO — JULES STUDIO
A3: STT | B3: Loại Website | C3: Giá từ (VNĐ) | D3: Thời gian | E3: Ghi chú
A4: 1 | B4: Landing Page (1 trang) | C4: 5,000,000 – 8,000,000 | D4: 5 – 7 ngày | E4: Responsive, Form, SEO, FAB
A5: 2 | B5: Website Giới Thiệu (3-6 trang) | C5: 5,000,000 – 12,000,000 | D5: 5 – 12 ngày | E5: Portfolio, Testimonials, Blog
A6: 3 | B6: Website Doanh Nghiệp (5-10 trang) | C6: 8,000,000 – 18,000,000 | D6: 8 – 18 ngày | E6: CMS, Dashboard, SEO nâng cao
A7: 4 | B7: E-commerce | C7: 15,000,000 – 35,000,000 | D7: 15 – 35 ngày | E7: Cart, Payment, Admin, Auth
A8: 5 | B8: Web App (ứng dụng web) | C8: 20,000,000 – 60,000,000+ | D8: 20 – 60 ngày | E8: Auth, CRUD, Dashboard, API
A9: 6 | B9: Booking (đặt lịch) | C9: 10,000,000 – 25,000,000 | D9: 10 – 25 ngày | E9: Calendar, Payment, Admin
A10: 7 | B10: Blog / Tạp Chí | C10: 5,000,000 – 10,000,000 | D10: 5 – 10 ngày | E10: CMS, SEO, Categories
A13: ⚠️ Giá chỉ mang tính tham khảo. Giá chính thức tùy thuộc yêu cầu cụ thể và tính năng được chọn.

Sheet Landing Page
A1: 📋 LANDING PAGE — BẢNG TÍNH NĂNG
A3: STT | B3: Tính năng | C3: Mức độ | D3: Có / Không | E3: Hệ số | F3: Ghi chú
A4: ⚙️ CORE (Trang cơ bản)
A5: 1 | B5: Homepage (hero + sections + CTA) | C5: 🟢 Bắt buộc | D5: =IF(AND('📋 Thông Tin'!$B$10="Landing Page",OR(C5="🟢 Bắt buộc",AND(C5="🟡 Nên có",OR('📋 Thông Tin'!$D$10="Phổ thông (🟢+🟡)",'📋 Thông Tin'!$D$10="Nâng cao (🟢+🟡+⚪)")),AND(C5="⚪ Tùy chọn",'📋 Thông Tin'!$D$10="Nâng cao (🟢+🟡+⚪)"))),"✓ Có","✗ Không") -> ✗ Không | E5: =IF(D5="✓ Có",VLOOKUP(B5,'Hệ Số'!B:C,2,FALSE),0) -> 0
A6: 2 | B6: About Page | C6: ⚪ Tùy chọn | D6: =IF(AND('📋 Thông Tin'!$B$10="Landing Page",OR(C6="🟢 Bắt buộc",AND(C6="🟡 Nên có",OR('📋 Thông Tin'!$D$10="Phổ thông (🟢+🟡)",'📋 Thông Tin'!$D$10="Nâng cao (🟢+🟡+⚪)")),AND(C6="⚪ Tùy chọn",'📋 Thông Tin'!$D$10="Nâng cao (🟢+🟡+⚪)"))),"✓ Có","✗ Không") -> ✗ Không | E6: =IF(D6="✓ Có",VLOOKUP(B6,'Hệ Số'!B:C,2,FALSE),0) -> 0
A7: 3 | B7: Contact Page (form + map + info) | C7: 🟢 Bắt buộc | D7: =IF(AND('📋 Thông Tin'!$B$10="Landing Page",OR(C7="🟢 Bắt buộc",AND(C7="🟡 Nên có",OR('📋 Thông Tin'!$D$10="Phổ thông (🟢+🟡)",'📋 Thông Tin'!$D$10="Nâng cao (🟢+🟡+⚪)")),AND(C7="⚪ Tùy chọn",'📋 Thông Tin'!$D$10="Nâng cao (🟢+🟡+⚪)"))),"✓ Có","✗ Không") -> ✗ Không | E7: =IF(D7="✓ Có",VLOOKUP(B7,'Hệ Số'!B:C,2,FALSE),0) -> 0
A8: 4 | B8: 404 Page | C8: 🟢 Bắt buộc | D8: =IF(AND('📋 Thông Tin'!$B$10="Landing Page",OR(C8="🟢 Bắt buộc",AND(C8="🟡 Nên có",OR('📋 Thông Tin'!$D$10="Phổ thông (🟢+🟡)",'📋 Thông Tin'!$D$10="Nâng cao (🟢+🟡+⚪)")),AND(C8="⚪ Tùy chọn",'📋 Thông Tin'!$D$10="Nâng cao (🟢+🟡+⚪)"))),"✓ Có","✗ Không") -> ✗ Không | E8: =IF(D8="✓ Có",VLOOKUP(B8,'Hệ Số'!B:C,2,FALSE),0) -> 0
A9: 5 | B9: Footer + Header | C9: 🟢 Bắt buộc | D9: =IF(AND('📋 Thông Tin'!$B$10="Landing Page",OR(C9="🟢 Bắt buộc",AND(C9="🟡 Nên có",OR('📋 Thông Tin'!$D$10="Phổ thông (🟢+🟡)",'📋 Thông Tin'!$D$10="Nâng cao (🟢+🟡+⚪)")),AND(C9="⚪ Tùy chọn",'📋 Thông Tin'!$D$10="Nâng cao (🟢+🟡+⚪)"))),"✓ Có","✗ Không") -> ✗ Không | E9: =IF(D9="✓ Có",VLOOKUP(B9,'Hệ Số'!B:C,2,FALSE),0) -> 0 | F9: Responsive nav, logo
A10: 6 | B10: Form liên hệ (gửi email) | C10: 🟢 Bắt buộc | D10: =IF(AND('📋 Thông Tin'!$B$10="Landing Page",OR(C10="🟢 Bắt buộc",AND(C10="🟡 Nên có",OR('📋 Thông Tin'!$D$10="Phổ thông (🟢+🟡)",'📋 Thông Tin'!$D$10="Nâng cao (🟢+🟡+⚪)")),AND(C10="⚪ Tùy chọn",'📋 Thông Tin'!$D$10="Nâng cao (🟢+🟡+⚪)"))),"✓ Có","✗ Không") -> ✗ Không | E10: =IF(D10="✓ Có",VLOOKUP(B10,'Hệ Số'!B:C,2,FALSE),0) -> 0
A11: 7 | B11: FAB (Floating Action Button) | C11: 🟡 Nên có | D11: =IF(AND('📋 Thông Tin'!$B$10="Landing Page",OR(C11="🟢 Bắt buộc",AND(C11="🟡 Nên có",OR('📋 Thông Tin'!$D$10="Phổ thông (🟢+🟡)",'📋 Thông Tin'!$D$10="Nâng cao (🟢+🟡+⚪)")),AND(C11="⚪ Tùy chọn",'📋 Thông Tin'!$D$10="Nâng cao (🟢+🟡+⚪)"))),"✓ Có","✗ Không") -> ✗ Không | E11: =IF(D11="✓ Có",VLOOKUP(B11,'Hệ Số'!B:C,2,FALSE),0) -> 0 | F11: Nút nổi: gọi/Zalo/Messenger
A12: 8 | B12: Google Maps nhúng | C12: ⚪ Tùy chọn | D12: =IF(AND('📋 Thông Tin'!$B$10="Landing Page",OR(C12="🟢 Bắt buộc",AND(C12="🟡 Nên có",OR('📋 Thông Tin'!$D$10="Phổ thông (🟢+🟡)",'📋 Thông Tin'!$D$10="Nâng cao (🟢+🟡+⚪)")),AND(C12="⚪ Tùy chọn",'📋 Thông Tin'!$D$10="Nâng cao (🟢+🟡+⚪)"))),"✓ Có","✗ Không") -> ✗ Không | E12: =IF(D12="✓ Có",VLOOKUP(B12,'Hệ Số'!B:C,2,FALSE),0) -> 0
A13: 9 | B13: Nút gọi điện / Zalo / Messenger | C13: 🟡 Nên có | D13: =IF(AND('📋 Thông Tin'!$B$10="Landing Page",OR(C13="🟢 Bắt buộc",AND(C13="🟡 Nên có",OR('📋 Thông Tin'!$D$10="Phổ thông (🟢+🟡)",'📋 Thông Tin'!$D$10="Nâng cao (🟢+🟡+⚪)")),AND(C13="⚪ Tùy chọn",'📋 Thông Tin'!$D$10="Nâng cao (🟢+🟡+⚪)"))),"✓ Có","✗ Không") -> ✗ Không | E13: =IF(D13="✓ Có",VLOOKUP(B13,'Hệ Số'!B:C,2,FALSE),0) -> 0 | F13: Nếu không dùng FAB
A14: 📝 NỘI DUNG
A15: 10 | B15: Portfolio/Gallery Grid | C15: 🟡 Nên có | D15: =IF(AND('📋 Thông Tin'!$B$10="Landing Page",OR(C15="🟢 Bắt buộc",AND(C15="🟡 Nên có",OR('📋 Thông Tin'!$D$10="Phổ thông (🟢+🟡)",'📋 Thông Tin'!$D$10="Nâng cao (🟢+🟡+⚪)")),AND(C15="⚪ Tùy chọn",'📋 Thông Tin'!$D$10="Nâng cao (🟢+🟡+⚪)"))),"✓ Có","✗ Không") -> ✗ Không | E15: =IF(D15="✓ Có",VLOOKUP(B15,'Hệ Số'!B:C,2,FALSE),0) -> 0 | F15: Lưới dự án/album ảnh
A16: 11 | B16: Portfolio Detail | C16: ⚪ Tùy chọn | D16: =IF(AND('📋 Thông Tin'!$B$10="Landing Page",OR(C16="🟢 Bắt buộc",AND(C16="🟡 Nên có",OR('📋 Thông Tin'!$D$10="Phổ thông (🟢+🟡)",'📋 Thông Tin'!$D$10="Nâng cao (🟢+🟡+⚪)")),AND(C16="⚪ Tùy chọn",'📋 Thông Tin'!$D$10="Nâng cao (🟢+🟡+⚪)"))),"✓ Có","✗ Không") -> ✗ Không | E16: =IF(D16="✓ Có",VLOOKUP(B16,'Hệ Số'!B:C,2,FALSE),0) -> 0 | F16: Chi tiết dự án
A17: 12 | B17: Blog List + Detail | C17: ⚪ Tùy chọn | D17: =IF(AND('📋 Thông Tin'!$B$10="Landing Page",OR(C17="🟢 Bắt buộc",AND(C17="🟡 Nên có",OR('📋 Thông Tin'!$D$10="Phổ thông (🟢+🟡)",'📋 Thông Tin'!$D$10="Nâng cao (🟢+🟡+⚪)")),AND(C17="⚪ Tùy chọn",'📋 Thông Tin'!$D$10="Nâng cao (🟢+🟡+⚪)"))),"✓ Có","✗ Không") -> ✗ Không | E17: =IF(D17="✓ Có",VLOOKUP(B17,'Hệ Số'!B:C,2,FALSE),0) -> 0 | F17: Bài viết + phân loại + tag
A18: 13 | B18: FAQ Page | C18: ⚪ Tùy chọn | D18: =IF(AND('📋 Thông Tin'!$B$10="Landing Page",OR(C18="🟢 Bắt buộc",AND(C18="🟡 Nên có",OR('📋 Thông Tin'!$D$10="Phổ thông (🟢+🟡)",'📋 Thông Tin'!$D$10="Nâng cao (🟢+🟡+⚪)")),AND(C18="⚪ Tùy chọn",'📋 Thông Tin'!$D$10="Nâng cao (🟢+🟡+⚪)"))),"✓ Có","✗ Không") -> ✗ Không | E18: =IF(D18="✓ Có",VLOOKUP(B18,'Hệ Số'!B:C,2,FALSE),0) -> 0 | F18: Accordion Q&A
A19: 14 | B19: Testimonials Section | C19: 🟡 Nên có | D19: =IF(AND('📋 Thông Tin'!$B$10="Landing Page",OR(C19="🟢 Bắt buộc",AND(C19="🟡 Nên có",OR('📋 Thông Tin'!$D$10="Phổ thông (🟢+🟡)",'📋 Thông Tin'!$D$10="Nâng cao (🟢+🟡+⚪)")),AND(C19="⚪ Tùy chọn",'📋 Thông Tin'!$D$10="Nâng cao (🟢+🟡+⚪)"))),"✓ Có","✗ Không") -> ✗ Không | E19: =IF(D19="✓ Có",VLOOKUP(B19,'Hệ Số'!B:C,2,FALSE),0) -> 0 | F19: Đánh giá khách hàng
A20: 15 | B20: Video nhúng (YouTube, Vimeo) | C20: ⚪ Tùy chọn | D20: =IF(AND('📋 Thông Tin'!$B$10="Landing Page",OR(C20="🟢 Bắt buộc",AND(C20="🟡 Nên có",OR('📋 Thông Tin'!$D$10="Phổ thông (🟢+🟡)",'📋 Thông Tin'!$D$10="Nâng cao (🟢+🟡+⚪)")),AND(C20="⚪ Tùy chọn",'📋 Thông Tin'!$D$10="Nâng cao (🟢+🟡+⚪)"))),"✓ Có","✗ Không") -> ✗ Không | E20: =IF(D20="✓ Có",VLOOKUP(B20,'Hệ Số'!B:C,2,FALSE),0) -> 0
A21: 16 | B21: Banner / Slider quản lý | C21: ⚪ Tùy chọn | D21: =IF(AND('📋 Thông Tin'!$B$10="Landing Page",OR(C21="🟢 Bắt buộc",AND(C21="🟡 Nên có",OR('📋 Thông Tin'!$D$10="Phổ thông (🟢+🟡)",'📋 Thông Tin'!$D$10="Nâng cao (🟢+🟡+⚪)")),AND(C21="⚪ Tùy chọn",'📋 Thông Tin'!$D$10="Nâng cao (🟢+🟡+⚪)"))),"✓ Có","✗ Không") -> ✗ Không | E21: =IF(D21="✓ Có",VLOOKUP(B21,'Hệ Số'!B:C,2,FALSE),0) -> 0 | F21: Admin quản lý banner
A22: 🛒 BOOKING & THƯƠNG MẠI
A23: 17 | B23: Booking Form (đơn giản) | C23: ⚪ Tùy chọn | D23: =IF(AND('📋 Thông Tin'!$B$10="Landing Page",OR(C23="🟢 Bắt buộc",AND(C23="🟡 Nên có",OR('📋 Thông Tin'!$D$10="Phổ thông (🟢+🟡)",'📋 Thông Tin'!$D$10="Nâng cao (🟢+🟡+⚪)")),AND(C23="⚪ Tùy chọn",'📋 Thông Tin'!$D$10="Nâng cao (🟢+🟡+⚪)"))),"✓ Có","✗ Không") -> ✗ Không | E23: =IF(D23="✓ Có",VLOOKUP(B23,'Hệ Số'!B:C,2,FALSE),0) -> 0 | F23: Form đặt lịch cơ bản
A24: 📊 ADMIN & QUẢN TRỊ
A25: 18 | B25: Dashboard Admin (CRUD cơ bản) | C25: ⚪ Tùy chọn | D25: =IF(AND('📋 Thông Tin'!$B$10="Landing Page",OR(C25="🟢 Bắt buộc",AND(C25="🟡 Nên có",OR('📋 Thông Tin'!$D$10="Phổ thông (🟢+🟡)",'📋 Thông Tin'!$D$10="Nâng cao (🟢+🟡+⚪)")),AND(C25="⚪ Tùy chọn",'📋 Thông Tin'!$D$10="Nâng cao (🟢+🟡+⚪)"))),"✓ Có","✗ Không") -> ✗ Không | E25: =IF(D25="✓ Có",VLOOKUP(B25,'Hệ Số'!B:C,2,FALSE),0) -> 0 | F25: Quản lý dữ liệu
A26: 🔔 THÔNG BÁO
A27: 19 | B27: Email notification | C27: 🟡 Nên có | D27: =IF(AND('📋 Thông Tin'!$B$10="Landing Page",OR(C27="🟢 Bắt buộc",AND(C27="🟡 Nên có",OR('📋 Thông Tin'!$D$10="Phổ thông (🟢+🟡)",'📋 Thông Tin'!$D$10="Nâng cao (🟢+🟡+⚪)")),AND(C27="⚪ Tùy chọn",'📋 Thông Tin'!$D$10="Nâng cao (🟢+🟡+⚪)"))),"✓ Có","✗ Không") -> ✗ Không | E27: =IF(D27="✓ Có",VLOOKUP(B27,'Hệ Số'!B:C,2,FALSE),0) -> 0 | F27: SendGrid
A28: 20 | B28: FCM Push Notification | C28: ⚪ Tùy chọn | D28: =IF(AND('📋 Thông Tin'!$B$10="Landing Page",OR(C28="🟢 Bắt buộc",AND(C28="🟡 Nên có",OR('📋 Thông Tin'!$D$10="Phổ thông (🟢+🟡)",'📋 Thông Tin'!$D$10="Nâng cao (🟢+🟡+⚪)")),AND(C28="⚪ Tùy chọn",'📋 Thông Tin'!$D$10="Nâng cao (🟢+🟡+⚪)"))),"✓ Có","✗ Không") -> ✗ Không | E28: =IF(D28="✓ Có",VLOOKUP(B28,'Hệ Số'!B:C,2,FALSE),0) -> 0 | F28: Push trình duyệt
A29: 🔧 KỸ THUẬT
A30: 21 | B30: Responsive (mobile + tablet) | C30: 🟢 Bắt buộc | D30: =IF(AND('📋 Thông Tin'!$B$10="Landing Page",OR(C30="🟢 Bắt buộc",AND(C30="🟡 Nên có",OR('📋 Thông Tin'!$D$10="Phổ thông (🟢+🟡)",'📋 Thông Tin'!$D$10="Nâng cao (🟢+🟡+⚪)")),AND(C30="⚪ Tùy chọn",'📋 Thông Tin'!$D$10="Nâng cao (🟢+🟡+⚪)"))),"✓ Có","✗ Không") -> ✗ Không | E30: =IF(D30="✓ Có",VLOOKUP(B30,'Hệ Số'!B:C,2,FALSE),0) -> 0
A31: 22 | B31: SEO cơ bản (meta, sitemap, robots) | C31: 🟢 Bắt buộc | D31: =IF(AND('📋 Thông Tin'!$B$10="Landing Page",OR(C31="🟢 Bắt buộc",AND(C31="🟡 Nên có",OR('📋 Thông Tin'!$D$10="Phổ thông (🟢+🟡)",'📋 Thông Tin'!$D$10="Nâng cao (🟢+🟡+⚪)")),AND(C31="⚪ Tùy chọn",'📋 Thông Tin'!$D$10="Nâng cao (🟢+🟡+⚪)"))),"✓ Có","✗ Không") -> ✗ Không | E31: =IF(D31="✓ Có",VLOOKUP(B31,'Hệ Số'!B:C,2,FALSE),0) -> 0
A32: 23 | B32: SEO nâng cao (schema markup) | C32: ⚪ Tùy chọn | D32: =IF(AND('📋 Thông Tin'!$B$10="Landing Page",OR(C32="🟢 Bắt buộc",AND(C32="🟡 Nên có",OR('📋 Thông Tin'!$D$10="Phổ thông (🟢+🟡)",'📋 Thông Tin'!$D$10="Nâng cao (🟢+🟡+⚪)")),AND(C32="⚪ Tùy chọn",'📋 Thông Tin'!$D$10="Nâng cao (🟢+🟡+⚪)"))),"✓ Có","✗ Không") -> ✗ Không | E32: =IF(D32="✓ Có",VLOOKUP(B32,'Hệ Số'!B:C,2,FALSE),0) -> 0 | F32: Rich snippets
A33: 24 | B33: Open Graph (share Facebook đẹp) | C33: 🟡 Nên có | D33: =IF(AND('📋 Thông Tin'!$B$10="Landing Page",OR(C33="🟢 Bắt buộc",AND(C33="🟡 Nên có",OR('📋 Thông Tin'!$D$10="Phổ thông (🟢+🟡)",'📋 Thông Tin'!$D$10="Nâng cao (🟢+🟡+⚪)")),AND(C33="⚪ Tùy chọn",'📋 Thông Tin'!$D$10="Nâng cao (🟢+🟡+⚪)"))),"✓ Có","✗ Không") -> ✗ Không | E33: =IF(D33="✓ Có",VLOOKUP(B33,'Hệ Số'!B:C,2,FALSE),0) -> 0
A34: 25 | B34: Google Analytics / Tag Manager | C34: 🟡 Nên có | D34: =IF(AND('📋 Thông Tin'!$B$10="Landing Page",OR(C34="🟢 Bắt buộc",AND(C34="🟡 Nên có",OR('📋 Thông Tin'!$D$10="Phổ thông (🟢+🟡)",'📋 Thông Tin'!$D$10="Nâng cao (🟢+🟡+⚪)")),AND(C34="⚪ Tùy chọn",'📋 Thông Tin'!$D$10="Nâng cao (🟢+🟡+⚪)"))),"✓ Có","✗ Không") -> ✗ Không | E34: =IF(D34="✓ Có",VLOOKUP(B34,'Hệ Số'!B:C,2,FALSE),0) -> 0
A35: 26 | B35: Facebook Pixel | C35: ⚪ Tùy chọn | D35: =IF(AND('📋 Thông Tin'!$B$10="Landing Page",OR(C35="🟢 Bắt buộc",AND(C35="🟡 Nên có",OR('📋 Thông Tin'!$D$10="Phổ thông (🟢+🟡)",'📋 Thông Tin'!$D$10="Nâng cao (🟢+🟡+⚪)")),AND(C35="⚪ Tùy chọn",'📋 Thông Tin'!$D$10="Nâng cao (🟢+🟡+⚪)"))),"✓ Có","✗ Không") -> ✗ Không | E35: =IF(D35="✓ Có",VLOOKUP(B35,'Hệ Số'!B:C,2,FALSE),0) -> 0
A36: 27 | B36: SSL Certificate (HTTPS) | C36: 🟢 Bắt buộc | D36: =IF(AND('📋 Thông Tin'!$B$10="Landing Page",OR(C36="🟢 Bắt buộc",AND(C36="🟡 Nên có",OR('📋 Thông Tin'!$D$10="Phổ thông (🟢+🟡)",'📋 Thông Tin'!$D$10="Nâng cao (🟢+🟡+⚪)")),AND(C36="⚪ Tùy chọn",'📋 Thông Tin'!$D$10="Nâng cao (🟢+🟡+⚪)"))),"✓ Có","✗ Không") -> ✗ Không | E36: =IF(D36="✓ Có",VLOOKUP(B36,'Hệ Số'!B:C,2,FALSE),0) -> 0 | F36: Miễn phí (Cloudflare)
A37: 28 | B37: PWA (offline + install) | C37: ⚪ Tùy chọn | D37: =IF(AND('📋 Thông Tin'!$B$10="Landing Page",OR(C37="🟢 Bắt buộc",AND(C37="🟡 Nên có",OR('📋 Thông Tin'!$D$10="Phổ thông (🟢+🟡)",'📋 Thông Tin'!$D$10="Nâng cao (🟢+🟡+⚪)")),AND(C37="⚪ Tùy chọn",'📋 Thông Tin'!$D$10="Nâng cao (🟢+🟡+⚪)"))),"✓ Có","✗ Không") -> ✗ Không | E37: =IF(D37="✓ Có",VLOOKUP(B37,'Hệ Số'!B:C,2,FALSE),0) -> 0
A38: 29 | B38: Multi-language (i18n) | C38: ⚪ Tùy chọn | D38: =IF(AND('📋 Thông Tin'!$B$10="Landing Page",OR(C38="🟢 Bắt buộc",AND(C38="🟡 Nên có",OR('📋 Thông Tin'!$D$10="Phổ thông (🟢+🟡)",'📋 Thông Tin'!$D$10="Nâng cao (🟢+🟡+⚪)")),AND(C38="⚪ Tùy chọn",'📋 Thông Tin'!$D$10="Nâng cao (🟢+🟡+⚪)"))),"✓ Có","✗ Không") -> ✗ Không | E38: =IF(D38="✓ Có",VLOOKUP(B38,'Hệ Số'!B:C,2,FALSE),0) -> 0 | F38: VI / EN
A39: 30 | B39: Performance optimization | C39: 🟡 Nên có | D39: =IF(AND('📋 Thông Tin'!$B$10="Landing Page",OR(C39="🟢 Bắt buộc",AND(C39="🟡 Nên có",OR('📋 Thông Tin'!$D$10="Phổ thông (🟢+🟡)",'📋 Thông Tin'!$D$10="Nâng cao (🟢+🟡+⚪)")),AND(C39="⚪ Tùy chọn",'📋 Thông Tin'!$D$10="Nâng cao (🟢+🟡+⚪)"))),"✓ Có","✗ Không") -> ✗ Không | E39: =IF(D39="✓ Có",VLOOKUP(B39,'Hệ Số'!B:C,2,FALSE),0) -> 0 | F39: Lighthouse, lazy load
A40: 31 | B40: Schema Markup (Rich Snippets) | C40: ⚪ Tùy chọn | D40: =IF(AND('📋 Thông Tin'!$B$10="Landing Page",OR(C40="🟢 Bắt buộc",AND(C40="🟡 Nên có",OR('📋 Thông Tin'!$D$10="Phổ thông (🟢+🟡)",'📋 Thông Tin'!$D$10="Nâng cao (🟢+🟡+⚪)")),AND(C40="⚪ Tùy chọn",'📋 Thông Tin'!$D$10="Nâng cao (🟢+🟡+⚪)"))),"✓ Có","✗ Không") -> ✗ Không | E40: =IF(D40="✓ Có",VLOOKUP(B40,'Hệ Số'!B:C,2,FALSE),0) -> 0
A41: 🎬 ĐỘ PHỨC TẠP THIẾT KẾ
...

Sheet Web Giới Thiệu
A1: 📋 WEB GIỚI THIỆU — BẢNG TÍNH NĂNG
A3: STT | B3: Tính năng | C3: Mức độ | D3: Có / Không | E3: Hệ số | F3: Ghi chú
A4: ⚙️ CORE (Trang cơ bản)
A5: 1 | B5: Homepage (hero + sections + CTA) | C5: 🟢 Bắt buộc | D5: =IF(AND('📋 Thông Tin'!$B$10="Web Giới Thiệu",OR(C5="🟢 Bắt buộc",AND(C5="🟡 Nên có",OR('📋 Thông Tin'!$D$10="Phổ thông (🟢+🟡)",'📋 Thông Tin'!$D$10="Nâng cao (🟢+🟡+⚪)")),AND(C5="⚪ Tùy chọn",'📋 Thông Tin'!$D$10="Nâng cao (🟢+🟡+⚪)"))),"✓ Có","✗ Không") -> ✗ Không | E5: =IF(D5="✓ Có",VLOOKUP(B5,'Hệ Số'!B:C,2,FALSE),0) -> 0
A6: 2 | B6: About Page | C6: 🟢 Bắt buộc | D6: =IF(AND('📋 Thông Tin'!$B$10="Web Giới Thiệu",OR(C6="🟢 Bắt buộc",AND(C6="🟡 Nên có",OR('📋 Thông Tin'!$D$10="Phổ thông (🟢+🟡)",'📋 Thông Tin'!$D$10="Nâng cao (🟢+🟡+⚪)")),AND(C6="⚪ Tùy chọn",'📋 Thông Tin'!$D$10="Nâng cao (🟢+🟡+⚪)"))),"✓ Có","✗ Không") -> ✗ Không | E6: =IF(D6="✓ Có",VLOOKUP(B6,'Hệ Số'!B:C,2,FALSE),0) -> 0
A7: 3 | B7: Contact Page (form + map + info) | C7: 🟢 Bắt buộc | D7: =IF(AND('📋 Thông Tin'!$B$10="Web Giới Thiệu",OR(C7="🟢 Bắt buộc",AND(C7="🟡 Nên có",OR('📋 Thông Tin'!$D$10="Phổ thông (🟢+🟡)",'📋 Thông Tin'!$D$10="Nâng cao (🟢+🟡+⚪)")),AND(C7="⚪ Tùy chọn",'📋 Thông Tin'!$D$10="Nâng cao (🟢+🟡+⚪)"))),"✓ Có","✗ Không") -> ✗ Không | E7: =IF(D7="✓ Có",VLOOKUP(B7,'Hệ Số'!B:C,2,FALSE),0) -> 0
A8: 4 | B8: 404 Page | C8: 🟢 Bắt buộc | D8: =IF(AND('📋 Thông Tin'!$B$10="Web Giới Thiệu",OR(C8="🟢 Bắt buộc",AND(C8="🟡 Nên có",OR('📋 Thông Tin'!$D$10="Phổ thông (🟢+🟡)",'📋 Thông Tin'!$D$10="Nâng cao (🟢+🟡+⚪)")),AND(C8="⚪ Tùy chọn",'📋 Thông Tin'!$D$10="Nâng cao (🟢+🟡+⚪)"))),"✓ Có","✗ Không") -> ✗ Không | E8: =IF(D8="✓ Có",VLOOKUP(B8,'Hệ Số'!B:C,2,FALSE),0) -> 0
A9: 5 | B9: Footer + Header | C9: 🟢 Bắt buộc | D9: =IF(AND('📋 Thông Tin'!$B$10="Web Giới Thiệu",OR(C9="🟢 Bắt buộc",AND(C9="🟡 Nên có",OR('📋 Thông Tin'!$D$10="Phổ thông (🟢+🟡)",'📋 Thông Tin'!$D$10="Nâng cao (🟢+🟡+⚪)")),AND(C9="⚪ Tùy chọn",'📋 Thông Tin'!$D$10="Nâng cao (🟢+🟡+⚪)"))),"✓ Có","✗ Không") -> ✗ Không | E9: =IF(D9="✓ Có",VLOOKUP(B9,'Hệ Số'!B:C,2,FALSE),0) -> 0 | F9: Responsive nav, logo
A10: 6 | B10: Form liên hệ (gửi email) | C10: 🟢 Bắt buộc | D10: =IF(AND('📋 Thông Tin'!$B$10="Web Giới Thiệu",OR(C10="🟢 Bắt buộc",AND(C10="🟡 Nên có",OR('📋 Thông Tin'!$D$10="Phổ thông (🟢+🟡)",'📋 Thông Tin'!$D$10="Nâng cao (🟢+🟡+⚪)")),AND(C10="⚪ Tùy chọn",'📋 Thông Tin'!$D$10="Nâng cao (🟢+🟡+⚪)"))),"✓ Có","✗ Không") -> ✗ Không | E10: =IF(D10="✓ Có",VLOOKUP(B10,'Hệ Số'!B:C,2,FALSE),0) -> 0
A11: 7 | B11: FAB (Floating Action Button) | C11: 🟡 Nên có | D11: =IF(AND('📋 Thông Tin'!$B$10="Web Giới Thiệu",OR(C11="🟢 Bắt buộc",AND(C11="🟡 Nên có",OR('📋 Thông Tin'!$D$10="Phổ thông (🟢+🟡)",'📋 Thông Tin'!$D$10="Nâng cao (🟢+🟡+⚪)")),AND(C11="⚪ Tùy chọn",'📋 Thông Tin'!$D$10="Nâng cao (🟢+🟡+⚪)"))),"✓ Có","✗ Không") -> ✗ Không | E11: =IF(D11="✓ Có",VLOOKUP(B11,'Hệ Số'!B:C,2,FALSE),0) -> 0 | F11: Nút nổi: gọi/Zalo/Messenger
A12: 8 | B12: Google Maps nhúng | C12: 🟡 Nên có | D12: =IF(AND('📋 Thông Tin'!$B$10="Web Giới Thiệu",OR(C12="🟢 Bắt buộc",AND(C12="🟡 Nên có",OR('📋 Thông Tin'!$D$10="Phổ thông (🟢+🟡)",'📋 Thông Tin'!$D$10="Nâng cao (🟢+🟡+⚪)")),AND(C12="⚪ Tùy chọn",'📋 Thông Tin'!$D$10="Nâng cao (🟢+🟡+⚪)"))),"✓ Có","✗ Không") -> ✗ Không | E12: =IF(D12="✓ Có",VLOOKUP(B12,'Hệ Số'!B:C,2,FALSE),0) -> 0
A13: 9 | B13: Nút gọi điện / Zalo / Messenger | C13: 🟡 Nên có | D13: =IF(AND('📋 Thông Tin'!$B$10="Web Giới Thiệu",OR(C13="🟢 Bắt buộc",AND(C13="🟡 Nên có",OR('📋 Thông Tin'!$D$10="Phổ thông (🟢+🟡)",'📋 Thông Tin'!$D$10="Nâng cao (🟢+🟡+⚪)")),AND(C13="⚪ Tùy chọn",'📋 Thông Tin'!$D$10="Nâng cao (🟢+🟡+⚪)"))),"✓ Có","✗ Không") -> ✗ Không | E13: =IF(D13="✓ Có",VLOOKUP(B13,'Hệ Số'!B:C,2,FALSE),0) -> 0 | F13: Nếu không dùng FAB
A14: 📝 NỘI DUNG
A15: 10 | B15: Services/Products List | C15: 🟢 Bắt buộc | D15: =IF(AND('📋 Thông Tin'!$B$10="Web Giới Thiệu",OR(C15="🟢 Bắt buộc",AND(C15="🟡 Nên có",OR('📋 Thông Tin'!$D$10="Phổ thông (🟢+🟡)",'📋 Thông Tin'!$D$10="Nâng cao (🟢+🟡+⚪)")),AND(C15="⚪ Tùy chọn",'📋 Thông Tin'!$D$10="Nâng cao (🟢+🟡+⚪)"))),"✓ Có","✗ Không") -> ✗ Không | E15: =IF(D15="✓ Có",VLOOKUP(B15,'Hệ Số'!B:C,2,FALSE),0) -> 0 | F15: Danh sách dịch vụ/sản phẩm
A16: 11 | B16: Service/Product Detail | C16: 🟡 Nên có | D16: =IF(AND('📋 Thông Tin'!$B$10="Web Giới Thiệu",OR(C16="🟢 Bắt buộc",AND(C16="🟡 Nên có",OR('📋 Thông Tin'!$D$10="Phổ thông (🟢+🟡)",'📋 Thông Tin'!$D$10="Nâng cao (🟢+🟡+⚪)")),AND(C16="⚪ Tùy chọn",'📋 Thông Tin'!$D$10="Nâng cao (🟢+🟡+⚪)"))),"✓ Có","✗ Không") -> ✗ Không | E16: =IF(D16="✓ Có",VLOOKUP(B16,'Hệ Số'!B:C,2,FALSE),0) -> 0 | F16: Trang chi tiết
A17: 12 | B17: Portfolio/Gallery Grid | C17: 🟢 Bắt buộc | D17: =IF(AND('📋 Thông Tin'!$B$10="Web Giới Thiệu",OR(C17="🟢 Bắt buộc",AND(C17="🟡 Nên có",OR('📋 Thông Tin'!$D$10="Phổ thông (🟢+🟡)",'📋 Thông Tin'!$D$10="Nâng cao (🟢+🟡+⚪)")),AND(C17="⚪ Tùy chọn",'📋 Thông Tin'!$D$10="Nâng cao (🟢+🟡+⚪)"))),"✓ Có","✗ Không") -> ✗ Không | E17: =IF(D17="✓ Có",VLOOKUP(B17,'Hệ Số'!B:C,2,FALSE),0) -> 0 | F17: Lưới dự án/album ảnh
A18: 13 | B18: Portfolio Detail | C18: 🟡 Nên có | D18: =IF(AND('📋 Thông Tin'!$B$10="Web Giới Thiệu",OR(C18="🟢 Bắt buộc",AND(C18="🟡 Nên có",OR('📋 Thông Tin'!$D$10="Phổ thông (🟢+🟡)",'📋 Thông Tin'!$D$10="Nâng cao (🟢+🟡+⚪)")),AND(C18="⚪ Tùy chọn",'📋 Thông Tin'!$D$10="Nâng cao (🟢+🟡+⚪)"))),"✓ Có","✗ Không") -> ✗ Không | E18: =IF(D18="✓ Có",VLOOKUP(B18,'Hệ Số'!B:C,2,FALSE),0) -> 0 | F18: Chi tiết dự án
A19: 14 | B19: Blog List + Detail | C19: ⚪ Tùy chọn | D19: =IF(AND('📋 Thông Tin'!$B$10="Web Giới Thiệu",OR(C19="🟢 Bắt buộc",AND(C19="🟡 Nên có",OR('📋 Thông Tin'!$D$10="Phổ thông (🟢+🟡)",'📋 Thông Tin'!$D$10="Nâng cao (🟢+🟡+⚪)")),AND(C19="⚪ Tùy chọn",'📋 Thông Tin'!$D$10="Nâng cao (🟢+🟡+⚪)"))),"✓ Có","✗ Không") -> ✗ Không | E19: =IF(D19="✓ Có",VLOOKUP(B19,'Hệ Số'!B:C,2,FALSE),0) -> 0 | F19: Bài viết + phân loại + tag
A20: 15 | B20: FAQ Page | C20: ⚪ Tùy chọn | D20: =IF(AND('📋 Thông Tin'!$B$10="Web Giới Thiệu",OR(C20="🟢 Bắt buộc",AND(C20="🟡 Nên có",OR('📋 Thông Tin'!$D$10="Phổ thông (🟢+🟡)",'📋 Thông Tin'!$D$10="Nâng cao (🟢+🟡+⚪)")),AND(C20="⚪ Tùy chọn",'📋 Thông Tin'!$D$10="Nâng cao (🟢+🟡+⚪)"))),"✓ Có","✗ Không") -> ✗ Không | E20: =IF(D20="✓ Có",VLOOKUP(B20,'Hệ Số'!B:C,2,FALSE),0) -> 0 | F20: Accordion Q&A
A21: 16 | B21: Testimonials Section | C21: 🟡 Nên có | D21: =IF(AND('📋 Thông Tin'!$B$10="Web Giới Thiệu",OR(C21="🟢 Bắt buộc",AND(C21="🟡 Nên có",OR('📋 Thông Tin'!$D$10="Phổ thông (🟢+🟡)",'📋 Thông Tin'!$D$10="Nâng cao (🟢+🟡+⚪)")),AND(C21="⚪ Tùy chọn",'📋 Thông Tin'!$D$10="Nâng cao (🟢+🟡+⚪)"))),"✓ Có","✗ Không") -> ✗ Không | E21: =IF(D21="✓ Có",VLOOKUP(B21,'Hệ Số'!B:C,2,FALSE),0) -> 0 | F21: Đánh giá khách hàng
A22: 17 | B22: Video nhúng (YouTube, Vimeo) | C22: ⚪ Tùy chọn | D22: =IF(AND('📋 Thông Tin'!$B$10="Web Giới Thiệu",OR(C22="🟢 Bắt buộc",AND(C22="🟡 Nên có",OR('📋 Thông Tin'!$D$10="Phổ thông (🟢+🟡)",'📋 Thông Tin'!$D$10="Nâng cao (🟢+🟡+⚪)")),AND(C22="⚪ Tùy chọn",'📋 Thông Tin'!$D$10="Nâng cao (🟢+🟡+⚪)"))),"✓ Có","✗ Không") -> ✗ Không | E22: =IF(D22="✓ Có",VLOOKUP(B22,'Hệ Số'!B:C,2,FALSE),0) -> 0
A23: 18 | B23: Banner / Slider quản lý | C23: ⚪ Tùy chọn | D23: =IF(AND('📋 Thông Tin'!$B$10="Web Giới Thiệu",OR(C23="🟢 Bắt buộc",AND(C23="🟡 Nên có",OR('📋 Thông Tin'!$D$10="Phổ thông (🟢+🟡)",'📋 Thông Tin'!$D$10="Nâng cao (🟢+🟡+⚪)")),AND(C23="⚪ Tùy chọn",'📋 Thông Tin'!$D$10="Nâng cao (🟢+🟡+⚪)"))),"✓ Có","✗ Không") -> ✗ Không | E23: =IF(D23="✓ Có",VLOOKUP(B23,'Hệ Số'!B:C,2,FALSE),0) -> 0 | F23: Admin quản lý banner
A24: 🛒 BOOKING & THƯƠNG MẠI
A25: 19 | B25: Booking Form (đơn giản) | C25: ⚪ Tùy chọn | D25: =IF(AND('📋 Thông Tin'!$B$10="Web Giới Thiệu",OR(C25="🟢 Bắt buộc",AND(C25="🟡 Nên có",OR('📋 Thông Tin'!$D$10="Phổ thông (🟢+🟡)",'📋 Thông Tin'!$D$10="Nâng cao (🟢+🟡+⚪)")),AND(C25="⚪ Tùy chọn",'📋 Thông Tin'!$D$10="Nâng cao (🟢+🟡+⚪)"))),"✓ Có","✗ Không") -> ✗ Không | E25: =IF(D25="✓ Có",VLOOKUP(B25,'Hệ Số'!B:C,2,FALSE),0) -> 0 | F25: Form đặt lịch cơ bản
A26: 📊 ADMIN & QUẢN TRỊ
A27: 20 | B27: Dashboard Admin (CRUD cơ bản) | C27: ⚪ Tùy chọn | D27: =IF(AND('📋 Thông Tin'!$B$10="Web Giới Thiệu",OR(C27="🟢 Bắt buộc",AND(C27="🟡 Nên có",OR('📋 Thông Tin'!$D$10="Phổ thông (🟢+🟡)",'📋 Thông Tin'!$D$10="Nâng cao (🟢+🟡+⚪)")),AND(C27="⚪ Tùy chọn",'📋 Thông Tin'!$D$10="Nâng cao (🟢+🟡+⚪)"))),"✓ Có","✗ Không") -> ✗ Không | E27: =IF(D27="✓ Có",VLOOKUP(B27,'Hệ Số'!B:C,2,FALSE),0) -> 0 | F27: Quản lý dữ liệu
A28: 21 | B28: Site Config Editor | C28: ⚪ Tùy chọn | D28: =IF(AND('📋 Thông Tin'!$B$10="Web Giới Thiệu",OR(C28="🟢 Bắt buộc",AND(C28="🟡 Nên có",OR('📋 Thông Tin'!$D$10="Phổ thông (🟢+🟡)",'📋 Thông Tin'!$D$10="Nâng cao (🟢+🟡+⚪)")),AND(C28="⚪ Tùy chọn",'📋 Thông Tin'!$D$10="Nâng cao (🟢+🟡+⚪)"))),"✓ Có","✗ Không") -> ✗ Không | E28: =IF(D28="✓ Có",VLOOKUP(B28,'Hệ Số'!B:C,2,FALSE),0) -> 0 | F28: Cài đặt hệ thống
A29: 🔐 TÀI KHOẢN & BẢO MẬT
A30: 22 | B30: Login/Register (Firebase Auth) | C30: ⚪ Tùy chọn | D30: =IF(AND('📋 Thông Tin'!$B$10="Web Giới Thiệu",OR(C30="🟢 Bắt buộc",AND(C30="🟡 Nên có",OR('📋 Thông Tin'!$D$10="Phổ thông (🟢+🟡)",'📋 Thông Tin'!$D$10="Nâng cao (🟢+🟡+⚪)")),AND(C30="⚪ Tùy chọn",'📋 Thông Tin'!$D$10="Nâng cao (🟢+🟡+⚪)"))),"✓ Có","✗ Không") -> ✗ Không | E30: =IF(D30="✓ Có",VLOOKUP(B30,'Hệ Số'!B:C,2,FALSE),0) -> 0
A31: 23 | B31: Social Login (Google/Facebook) | C31: ⚪ Tùy chọn | D31: =IF(AND('📋 Thông Tin'!$B$10="Web Giới Thiệu",OR(C31="🟢 Bắt buộc",AND(C31="🟡 Nên có",OR('📋 Thông Tin'!$D$10="Phổ thông (🟢+🟡)",'📋 Thông Tin'!$D$10="Nâng cao (🟢+🟡+⚪)")),AND(C31="⚪ Tùy chọn",'📋 Thông Tin'!$D$10="Nâng cao (🟢+🟡+⚪)"))),"✓ Có","✗ Không") -> ✗ Không | E31: =IF(D31="✓ Có",VLOOKUP(B31,'Hệ Số'!B:C,2,FALSE),0) -> 0 | F31: OAuth2
A32: 🔔 THÔNG BÁO
A33: 24 | B33: Email notification | C33: 🟡 Nên có | D33: =IF(AND('📋 Thông Tin'!$B$10="Web Giới Thiệu",OR(C33="🟢 Bắt buộc",AND(C33="🟡 Nên có",OR('📋 Thông Tin'!$D$10="Phổ thông (🟢+🟡)",'📋 Thông Tin'!$D$10="Nâng cao (🟢+🟡+⚪)")),AND(C33="⚪ Tùy chọn",'📋 Thông Tin'!$D$10="Nâng cao (🟢+🟡+⚪)"))),"✓ Có","✗ Không") -> ✗ Không | E33: =IF(D33="✓ Có",VLOOKUP(B33,'Hệ Số'!B:C,2,FALSE),0) -> 0 | F33: SendGrid
A34: 25 | B34: Admin dashboard notification | C34: ⚪ Tùy chọn | D34: =IF(AND('📋 Thông Tin'!$B$10="Web Giới Thiệu",OR(C34="🟢 Bắt buộc",AND(C34="🟡 Nên có",OR('📋 Thông Tin'!$D$10="Phổ thông (🟢+🟡)",'📋 Thông Tin'!$D$10="Nâng cao (🟢+🟡+⚪)")),AND(C34="⚪ Tùy chọn",'📋 Thông Tin'!$D$10="Nâng cao (🟢+🟡+⚪)"))),"✓ Có","✗ Không") -> ✗ Không | E34: =IF(D34="✓ Có",VLOOKUP(B34,'Hệ Số'!B:C,2,FALSE),0) -> 0 | F34: Chuông thông báo
A35: 26 | B35: FCM Push Notification | C35: ⚪ Tùy chọn | D35: =IF(AND('📋 Thông Tin'!$B$10="Web Giới Thiệu",OR(C35="🟢 Bắt buộc",AND(C35="🟡 Nên có",OR('📋 Thông Tin'!$D$10="Phổ thông (🟢+🟡)",'📋 Thông Tin'!$D$10="Nâng cao (🟢+🟡+⚪)")),AND(C35="⚪ Tùy chọn",'📋 Thông Tin'!$D$10="Nâng cao (🟢+🟡+⚪)"))),"✓ Có","✗ Không") -> ✗ Không | E35: =IF(D35="✓ Có",VLOOKUP(B35,'Hệ Số'!B:C,2,FALSE),0) -> 0 | F35: Push trình duyệt
A36: 🔧 KỸ THUẬT
A37: 27 | B37: Responsive (mobile + tablet) | C37: 🟢 Bắt buộc | D37: =IF(AND('📋 Thông Tin'!$B$10="Web Giới Thiệu",OR(C37="🟢 Bắt buộc",AND(C37="🟡 Nên có",OR('📋 Thông Tin'!$D$10="Phổ thông (🟢+🟡)",'📋 Thông Tin'!$D$10="Nâng cao (🟢+🟡+⚪)")),AND(C37="⚪ Tùy chọn",'📋 Thông Tin'!$D$10="Nâng cao (🟢+🟡+⚪)"))),"✓ Có","✗ Không") -> ✗ Không | E37: =IF(D37="✓ Có",VLOOKUP(B37,'Hệ Số'!B:C,2,FALSE),0) -> 0
A38: 28 | B38: SEO cơ bản (meta, sitemap, robots) | C38: 🟢 Bắt buộc | D38: =IF(AND('📋 Thông Tin'!$B$10="Web Giới Thiệu",OR(C38="🟢 Bắt buộc",AND(C38="🟡 Nên có",OR('📋 Thông Tin'!$D$10="Phổ thông (🟢+🟡)",'📋 Thông Tin'!$D$10="Nâng cao (🟢+🟡+⚪)")),AND(C38="⚪ Tùy chọn",'📋 Thông Tin'!$D$10="Nâng cao (🟢+🟡+⚪)"))),"✓ Có","✗ Không") -> ✗ Không | E38: =IF(D38="✓ Có",VLOOKUP(B38,'Hệ Số'!B:C,2,FALSE),0) -> 0
A39: 29 | B39: SEO nâng cao (schema markup) | C39: ⚪ Tùy chọn | D39: =IF(AND('📋 Thông Tin'!$B$10="Web Giới Thiệu",OR(C39="🟢 Bắt buộc",AND(C39="🟡 Nên có",OR('📋 Thông Tin'!$D$10="Phổ thông (🟢+🟡)",'📋 Thông Tin'!$D$10="Nâng cao (🟢+🟡+⚪)")),AND(C39="⚪ Tùy chọn",'📋 Thông Tin'!$D$10="Nâng cao (🟢+🟡+⚪)"))),"✓ Có","✗ Không") -> ✗ Không | E39: =IF(D39="✓ Có",VLOOKUP(B39,'Hệ Số'!B:C,2,FALSE),0) -> 0 | F39: Rich snippets
A40: 30 | B40: Open Graph (share Facebook đẹp) | C40: 🟡 Nên có | D40: =IF(AND('📋 Thông Tin'!$B$10="Web Giới Thiệu",OR(C40="🟢 Bắt buộc",AND(C40="🟡 Nên có",OR('📋 Thông Tin'!$D$10="Phổ thông (🟢+🟡)",'📋 Thông Tin'!$D$10="Nâng cao (🟢+🟡+⚪)")),AND(C40="⚪ Tùy chọn",'📋 Thông Tin'!$D$10="Nâng cao (🟢+🟡+⚪)"))),"✓ Có","✗ Không") -> ✗ Không | E40: =IF(D40="✓ Có",VLOOKUP(B40,'Hệ Số'!B:C,2,FALSE),0) -> 0
A41: 31 | B41: Google Analytics / Tag Manager | C41: 🟡 Nên có | D41: =IF(AND('📋 Thông Tin'!$B$10="Web Giới Thiệu",OR(C41="🟢 Bắt buộc",AND(C41="🟡 Nên có",OR('📋 Thông Tin'!$D$10="Phổ thông (🟢+🟡)",'📋 Thông Tin'!$D$10="Nâng cao (🟢+🟡+⚪)")),AND(C41="⚪ Tùy chọn",'📋 Thông Tin'!$D$10="Nâng cao (🟢+🟡+⚪)"))),"✓ Có","✗ Không") -> ✗ Không | E41: =IF(D41="✓ Có",VLOOKUP(B41,'Hệ Số'!B:C,2,FALSE),0) -> 0
...

Sheet Web Doanh Nghiệp
A1: 📋 WEB DOANH NGHIỆP — BẢNG TÍNH NĂNG
A3: STT | B3: Tính năng | C3: Mức độ | D3: Có / Không | E3: Hệ số | F3: Ghi chú
A4: ⚙️ CORE (Trang cơ bản)
A5: 1 | B5: Homepage (hero + sections + CTA) | C5: 🟢 Bắt buộc | D5: =IF(AND('📋 Thông Tin'!$B$10="Web Doanh Nghiệp",OR(C5="🟢 Bắt buộc",AND(C5="🟡 Nên có",OR('📋 Thông Tin'!$D$10="Phổ thông (🟢+🟡)",'📋 Thông Tin'!$D$10="Nâng cao (🟢+🟡+⚪)")),AND(C5="⚪ Tùy chọn",'📋 Thông Tin'!$D$10="Nâng cao (🟢+🟡+⚪)"))),"✓ Có","✗ Không") -> ✗ Không | E5: =IF(D5="✓ Có",VLOOKUP(B5,'Hệ Số'!B:C,2,FALSE),0) -> 0
A6: 2 | B6: About Page | C6: 🟢 Bắt buộc | D6: =IF(AND('📋 Thông Tin'!$B$10="Web Doanh Nghiệp",OR(C6="🟢 Bắt buộc",AND(C6="🟡 Nên có",OR('📋 Thông Tin'!$D$10="Phổ thông (🟢+🟡)",'📋 Thông Tin'!$D$10="Nâng cao (🟢+🟡+⚪)")),AND(C6="⚪ Tùy chọn",'📋 Thông Tin'!$D$10="Nâng cao (🟢+🟡+⚪)"))),"✓ Có","✗ Không") -> ✗ Không | E6: =IF(D6="✓ Có",VLOOKUP(B6,'Hệ Số'!B:C,2,FALSE),0) -> 0
A7: 3 | B7: Contact Page (form + map + info) | C7: 🟢 Bắt buộc | D7: =IF(AND('📋 Thông Tin'!$B$10="Web Doanh Nghiệp",OR(C7="🟢 Bắt buộc",AND(C7="🟡 Nên có",OR('📋 Thông Tin'!$D$10="Phổ thông (🟢+🟡)",'📋 Thông Tin'!$D$10="Nâng cao (🟢+🟡+⚪)")),AND(C7="⚪ Tùy chọn",'📋 Thông Tin'!$D$10="Nâng cao (🟢+🟡+⚪)"))),"✓ Có","✗ Không") -> ✗ Không | E7: =IF(D7="✓ Có",VLOOKUP(B7,'Hệ Số'!B:C,2,FALSE),0) -> 0
A8: 4 | B8: 404 Page | C8: 🟢 Bắt buộc | D8: =IF(AND('📋 Thông Tin'!$B$10="Web Doanh Nghiệp",OR(C8="🟢 Bắt buộc",AND(C8="🟡 Nên có",OR('📋 Thông Tin'!$D$10="Phổ thông (🟢+🟡)",'📋 Thông Tin'!$D$10="Nâng cao (🟢+🟡+⚪)")),AND(C8="⚪ Tùy chọn",'📋 Thông Tin'!$D$10="Nâng cao (🟢+🟡+⚪)"))),"✓ Có","✗ Không") -> ✗ Không | E8: =IF(D8="✓ Có",VLOOKUP(B8,'Hệ Số'!B:C,2,FALSE),0) -> 0
A9: 5 | B9: Footer + Header | C9: 🟢 Bắt buộc | D9: =IF(AND('📋 Thông Tin'!$B$10="Web Doanh Nghiệp",OR(C9="🟢 Bắt buộc",AND(C9="🟡 Nên có",OR('📋 Thông Tin'!$D$10="Phổ thông (🟢+🟡)",'📋 Thông Tin'!$D$10="Nâng cao (🟢+🟡+⚪)")),AND(C9="⚪ Tùy chọn",'📋 Thông Tin'!$D$10="Nâng cao (🟢+🟡+⚪)"))),"✓ Có","✗ Không") -> ✗ Không | E9: =IF(D9="✓ Có",VLOOKUP(B9,'Hệ Số'!B:C,2,FALSE),0) -> 0 | F9: Responsive nav, logo
A10: 6 | B10: Form liên hệ (gửi email) | C10: 🟢 Bắt buộc | D10: =IF(AND('📋 Thông Tin'!$B$10="Web Doanh Nghiệp",OR(C10="🟢 Bắt buộc",AND(C10="🟡 Nên có",OR('📋 Thông Tin'!$D$10="Phổ thông (🟢+🟡)",'📋 Thông Tin'!$D$10="Nâng cao (🟢+🟡+⚪)")),AND(C10="⚪ Tùy chọn",'📋 Thông Tin'!$D$10="Nâng cao (🟢+🟡+⚪)"))),"✓ Có","✗ Không") -> ✗ Không | E10: =IF(D10="✓ Có",VLOOKUP(B10,'Hệ Số'!B:C,2,FALSE),0) -> 0
A11: 7 | B11: FAB (Floating Action Button) | C11: 🟡 Nên có | D11: =IF(AND('📋 Thông Tin'!$B$10="Web Doanh Nghiệp",OR(C11="🟢 Bắt buộc",AND(C11="🟡 Nên có",OR('📋 Thông Tin'!$D$10="Phổ thông (🟢+🟡)",'📋 Thông Tin'!$D$10="Nâng cao (🟢+🟡+⚪)")),AND(C11="⚪ Tùy chọn",'📋 Thông Tin'!$D$10="Nâng cao (🟢+🟡+⚪)"))),"✓ Có","✗ Không") -> ✗ Không | E11: =IF(D11="✓ Có",VLOOKUP(B11,'Hệ Số'!B:C,2,FALSE),0) -> 0 | F11: Nút nổi: gọi/Zalo/Messenger
A12: 8 | B12: Google Maps nhúng | C12: 🟡 Nên có | D12: =IF(AND('📋 Thông Tin'!$B$10="Web Doanh Nghiệp",OR(C12="🟢 Bắt buộc",AND(C12="🟡 Nên có",OR('📋 Thông Tin'!$D$10="Phổ thông (🟢+🟡)",'📋 Thông Tin'!$D$10="Nâng cao (🟢+🟡+⚪)")),AND(C12="⚪ Tùy chọn",'📋 Thông Tin'!$D$10="Nâng cao (🟢+🟡+⚪)"))),"✓ Có","✗ Không") -> ✗ Không | E12: =IF(D12="✓ Có",VLOOKUP(B12,'Hệ Số'!B:C,2,FALSE),0) -> 0
A13: 9 | B13: Nút gọi điện / Zalo / Messenger | C13: 🟡 Nên có | D13: =IF(AND('📋 Thông Tin'!$B$10="Web Doanh Nghiệp",OR(C13="🟢 Bắt buộc",AND(C13="🟡 Nên có",OR('📋 Thông Tin'!$D$10="Phổ thông (🟢+🟡)",'📋 Thông Tin'!$D$10="Nâng cao (🟢+🟡+⚪)")),AND(C13="⚪ Tùy chọn",'📋 Thông Tin'!$D$10="Nâng cao (🟢+🟡+⚪)"))),"✓ Có","✗ Không") -> ✗ Không | E13: =IF(D13="✓ Có",VLOOKUP(B13,'Hệ Số'!B:C,2,FALSE),0) -> 0 | F13: Nếu không dùng FAB
A14: 📝 NỘI DUNG
A15: 10 | B15: Services/Products List | C15: 🟢 Bắt buộc | D15: =IF(AND('📋 Thông Tin'!$B$10="Web Doanh Nghiệp",OR(C15="🟢 Bắt buộc",AND(C15="🟡 Nên có",OR('📋 Thông Tin'!$D$10="Phổ thông (🟢+🟡)",'📋 Thông Tin'!$D$10="Nâng cao (🟢+🟡+⚪)")),AND(C15="⚪ Tùy chọn",'📋 Thông Tin'!$D$10="Nâng cao (🟢+🟡+⚪)"))),"✓ Có","✗ Không") -> ✗ Không | E15: =IF(D15="✓ Có",VLOOKUP(B15,'Hệ Số'!B:C,2,FALSE),0) -> 0 | F15: Danh sách dịch vụ/sản phẩm
A16: 11 | B16: Service/Product Detail | C16: 🟡 Nên có | D16: =IF(AND('📋 Thông Tin'!$B$10="Web Doanh Nghiệp",OR(C16="🟢 Bắt buộc",AND(C16="🟡 Nên có",OR('📋 Thông Tin'!$D$10="Phổ thông (🟢+🟡)",'📋 Thông Tin'!$D$10="Nâng cao (🟢+🟡+⚪)")),AND(C16="⚪ Tùy chọn",'📋 Thông Tin'!$D$10="Nâng cao (🟢+🟡+⚪)"))),"✓ Có","✗ Không") -> ✗ Không | E16: =IF(D16="✓ Có",VLOOKUP(B16,'Hệ Số'!B:C,2,FALSE),0) -> 0 | F16: Trang chi tiết
A17: 12 | B17: Portfolio/Gallery Grid | C17: 🟢 Bắt buộc | D17: =IF(AND('📋 Thông Tin'!$B$10="Web Doanh Nghiệp",OR(C17="🟢 Bắt buộc",AND(C17="🟡 Nên có",OR('📋 Thông Tin'!$D$10="Phổ thông (🟢+🟡)",'📋 Thông Tin'!$D$10="Nâng cao (🟢+🟡+⚪)")),AND(C17="⚪ Tùy chọn",'📋 Thông Tin'!$D$10="Nâng cao (🟢+🟡+⚪)"))),"✓ Có","✗ Không") -> ✗ Không | E17: =IF(D17="✓ Có",VLOOKUP(B17,'Hệ Số'!B:C,2,FALSE),0) -> 0 | F17: Lưới dự án/album ảnh
A18: 13 | B18: Portfolio Detail | C18: 🟡 Nên có | D18: =IF(AND('📋 Thông Tin'!$B$10="Web Doanh Nghiệp",OR(C18="🟢 Bắt buộc",AND(C18="🟡 Nên có",OR('📋 Thông Tin'!$D$10="Phổ thông (🟢+🟡)",'📋 Thông Tin'!$D$10="Nâng cao (🟢+🟡+⚪)")),AND(C18="⚪ Tùy chọn",'📋 Thông Tin'!$D$10="Nâng cao (🟢+🟡+⚪)"))),"✓ Có","✗ Không") -> ✗ Không | E18: =IF(D18="✓ Có",VLOOKUP(B18,'Hệ Số'!B:C,2,FALSE),0) -> 0 | F18: Chi tiết dự án
A19: 14 | B19: Blog List + Detail | C19: 🟡 Nên có | D19: =IF(AND('📋 Thông Tin'!$B$10="Web Doanh Nghiệp",OR(C19="🟢 Bắt buộc",AND(C19="🟡 Nên có",OR('📋 Thông Tin'!$D$10="Phổ thông (🟢+🟡)",'📋 Thông Tin'!$D$10="Nâng cao (🟢+🟡+⚪)")),AND(C19="⚪ Tùy chọn",'📋 Thông Tin'!$D$10="Nâng cao (🟢+🟡+⚪)"))),"✓ Có","✗ Không") -> ✗ Không | E19: =IF(D19="✓ Có",VLOOKUP(B19,'Hệ Số'!B:C,2,FALSE),0) -> 0 | F19: Bài viết + phân loại + tag
A20: 15 | B20: FAQ Page | C20: 🟡 Nên có | D20: =IF(AND('📋 Thông Tin'!$B$10="Web Doanh Nghiệp",OR(C20="🟢 Bắt buộc",AND(C20="🟡 Nên có",OR('📋 Thông Tin'!$D$10="Phổ thông (🟢+🟡)",'📋 Thông Tin'!$D$10="Nâng cao (🟢+🟡+⚪)")),AND(C20="⚪ Tùy chọn",'📋 Thông Tin'!$D$10="Nâng cao (🟢+🟡+⚪)"))),"✓ Có","✗ Không") -> ✗ Không | E20: =IF(D20="✓ Có",VLOOKUP(B20,'Hệ Số'!B:C,2,FALSE),0) -> 0 | F20: Accordion Q&A
A21: 16 | B21: Testimonials Section | C21: 🟡 Nên có | D21: =IF(AND('📋 Thông Tin'!$B$10="Web Doanh Nghiệp",OR(C21="🟢 Bắt buộc",AND(C21="🟡 Nên có",OR('📋 Thông Tin'!$D$10="Phổ thông (🟢+🟡)",'📋 Thông Tin'!$D$10="Nâng cao (🟢+🟡+⚪)")),AND(C21="⚪ Tùy chọn",'📋 Thông Tin'!$D$10="Nâng cao (🟢+🟡+⚪)"))),"✓ Có","✗ Không") -> ✗ Không | E21: =IF(D21="✓ Có",VLOOKUP(B21,'Hệ Số'!B:C,2,FALSE),0) -> 0 | F21: Đánh giá khách hàng
A22: 17 | B22: Video nhúng (YouTube, Vimeo) | C22: ⚪ Tùy chọn | D22: =IF(AND('📋 Thông Tin'!$B$10="Web Doanh Nghiệp",OR(C22="🟢 Bắt buộc",AND(C22="🟡 Nên có",OR('📋 Thông Tin'!$D$10="Phổ thông (🟢+🟡)",'📋 Thông Tin'!$D$10="Nâng cao (🟢+🟡+⚪)")),AND(C22="⚪ Tùy chọn",'📋 Thông Tin'!$D$10="Nâng cao (🟢+🟡+⚪)"))),"✓ Có","✗ Không") -> ✗ Không | E22: =IF(D22="✓ Có",VLOOKUP(B22,'Hệ Số'!B:C,2,FALSE),0) -> 0
A23: 18 | B23: Banner / Slider quản lý | C23: 🟡 Nên có | D23: =IF(AND('📋 Thông Tin'!$B$10="Web Doanh Nghiệp",OR(C23="🟢 Bắt buộc",AND(C23="🟡 Nên có",OR('📋 Thông Tin'!$D$10="Phổ thông (🟢+🟡)",'📋 Thông Tin'!$D$10="Nâng cao (🟢+🟡+⚪)")),AND(C23="⚪ Tùy chọn",'📋 Thông Tin'!$D$10="Nâng cao (🟢+🟡+⚪)"))),"✓ Có","✗ Không") -> ✗ Không | E23: =IF(D23="✓ Có",VLOOKUP(B23,'Hệ Số'!B:C,2,FALSE),0) -> 0 | F23: Admin quản lý banner
A24: 19 | B24: Đánh giá / Review sản phẩm | C24: ⚪ Tùy chọn | D24: =IF(AND('📋 Thông Tin'!$B$10="Web Doanh Nghiệp",OR(C24="🟢 Bắt buộc",AND(C24="🟡 Nên có",OR('📋 Thông Tin'!$D$10="Phổ thông (🟢+🟡)",'📋 Thông Tin'!$D$10="Nâng cao (🟢+🟡+⚪)")),AND(C24="⚪ Tùy chọn",'📋 Thông Tin'!$D$10="Nâng cao (🟢+🟡+⚪)"))),"✓ Có","✗ Không") -> ✗ Không | E24: =IF(D24="✓ Có",VLOOKUP(B24,'Hệ Số'!B:C,2,FALSE),0) -> 0 | F24: Rating + comment
A25: 🛒 BOOKING & THƯƠNG MẠI
A26: 20 | B26: Booking Form (đơn giản) | C26: ⚪ Tùy chọn | D26: =IF(AND('📋 Thông Tin'!$B$10="Web Doanh Nghiệp",OR(C26="🟢 Bắt buộc",AND(C26="🟡 Nên có",OR('📋 Thông Tin'!$D$10="Phổ thông (🟢+🟡)",'📋 Thông Tin'!$D$10="Nâng cao (🟢+🟡+⚪)")),AND(C26="⚪ Tùy chọn",'📋 Thông Tin'!$D$10="Nâng cao (🟢+🟡+⚪)"))),"✓ Có","✗ Không") -> ✗ Không | E26: =IF(D26="✓ Có",VLOOKUP(B26,'Hệ Số'!B:C,2,FALSE),0) -> 0 | F26: Form đặt lịch cơ bản
A27: 📊 ADMIN & QUẢN TRỊ
A28: 21 | B28: Dashboard Admin (CRUD cơ bản) | C28: 🟡 Nên có | D28: =IF(AND('📋 Thông Tin'!$B$10="Web Doanh Nghiệp",OR(C28="🟢 Bắt buộc",AND(C28="🟡 Nên có",OR('📋 Thông Tin'!$D$10="Phổ thông (🟢+🟡)",'📋 Thông Tin'!$D$10="Nâng cao (🟢+🟡+⚪)")),AND(C28="⚪ Tùy chọn",'📋 Thông Tin'!$D$10="Nâng cao (🟢+🟡+⚪)"))),"✓ Có","✗ Không") -> ✗ Không | E28: =IF(D28="✓ Có",VLOOKUP(B28,'Hệ Số'!B:C,2,FALSE),0) -> 0 | F28: Quản lý dữ liệu
A29: 22 | B29: Dashboard Full (CRUD + analytics) | C29: ⚪ Tùy chọn | D29: =IF(AND('📋 Thông Tin'!$B$10="Web Doanh Nghiệp",OR(C29="🟢 Bắt buộc",AND(C29="🟡 Nên có",OR('📋 Thông Tin'!$D$10="Phổ thông (🟢+🟡)",'📋 Thông Tin'!$D$10="Nâng cao (🟢+🟡+⚪)")),AND(C29="⚪ Tùy chọn",'📋 Thông Tin'!$D$10="Nâng cao (🟢+🟡+⚪)"))),"✓ Có","✗ Không") -> ✗ Không | E29: =IF(D29="✓ Có",VLOOKUP(B29,'Hệ Số'!B:C,2,FALSE),0) -> 0 | F29: Charts, KPIs, reports
A30: 23 | B30: Site Config Editor | C30: ⚪ Tùy chọn | D30: =IF(AND('📋 Thông Tin'!$B$10="Web Doanh Nghiệp",OR(C30="🟢 Bắt buộc",AND(C30="🟡 Nên có",OR('📋 Thông Tin'!$D$10="Phổ thông (🟢+🟡)",'📋 Thông Tin'!$D$10="Nâng cao (🟢+🟡+⚪)")),AND(C30="⚪ Tùy chọn",'📋 Thông Tin'!$D$10="Nâng cao (🟢+🟡+⚪)"))),"✓ Có","✗ Không") -> ✗ Không | E30: =IF(D30="✓ Có",VLOOKUP(B30,'Hệ Số'!B:C,2,FALSE),0) -> 0 | F30: Cài đặt hệ thống
A31: 24 | B31: User Management | C31: ⚪ Tùy chọn | D31: =IF(AND('📋 Thông Tin'!$B$10="Web Doanh Nghiệp",OR(C31="🟢 Bắt buộc",AND(C31="🟡 Nên có",OR('📋 Thông Tin'!$D$10="Phổ thông (🟢+🟡)",'📋 Thông Tin'!$D$10="Nâng cao (🟢+🟡+⚪)")),AND(C31="⚪ Tùy chọn",'📋 Thông Tin'!$D$10="Nâng cao (🟢+🟡+⚪)"))),"✓ Có","✗ Không") -> ✗ Không | E31: =IF(D31="✓ Có",VLOOKUP(B31,'Hệ Số'!B:C,2,FALSE),0) -> 0 | F31: Quản lý tài khoản
A32: 25 | B32: Xuất báo cáo (Excel, PDF) | C32: ⚪ Tùy chọn | D32: =IF(AND('📋 Thông Tin'!$B$10="Web Doanh Nghiệp",OR(C32="🟢 Bắt buộc",AND(C32="🟡 Nên có",OR('📋 Thông Tin'!$D$10="Phổ thông (🟢+🟡)",'📋 Thông Tin'!$D$10="Nâng cao (🟢+🟡+⚪)")),AND(C32="⚪ Tùy chọn",'📋 Thông Tin'!$D$10="Nâng cao (🟢+🟡+⚪)"))),"✓ Có","✗ Không") -> ✗ Không | E32: =IF(D32="✓ Có",VLOOKUP(B32,'Hệ Số'!B:C,2,FALSE),0) -> 0 | F32: Export reports
A33: 🔐 TÀI KHOẢN & BẢO MẬT
A34: 26 | B34: Login/Register (Firebase Auth) | C34: ⚪ Tùy chọn | D34: =IF(AND('📋 Thông Tin'!$B$10="Web Doanh Nghiệp",OR(C34="🟢 Bắt buộc",AND(C34="🟡 Nên có",OR('📋 Thông Tin'!$D$10="Phổ thông (🟢+🟡)",'📋 Thông Tin'!$D$10="Nâng cao (🟢+🟡+⚪)")),AND(C34="⚪ Tùy chọn",'📋 Thông Tin'!$D$10="Nâng cao (🟢+🟡+⚪)"))),"✓ Có","✗ Không") -> ✗ Không | E34: =IF(D34="✓ Có",VLOOKUP(B34,'Hệ Số'!B:C,2,FALSE),0) -> 0
A35: 27 | B35: Social Login (Google/Facebook) | C35: ⚪ Tùy chọn | D35: =IF(AND('📋 Thông Tin'!$B$10="Web Doanh Nghiệp",OR(C35="🟢 Bắt buộc",AND(C35="🟡 Nên có",OR('📋 Thông Tin'!$D$10="Phổ thông (🟢+🟡)",'📋 Thông Tin'!$D$10="Nâng cao (🟢+🟡+⚪)")),AND(C35="⚪ Tùy chọn",'📋 Thông Tin'!$D$10="Nâng cao (🟢+🟡+⚪)"))),"✓ Có","✗ Không") -> ✗ Không | E35: =IF(D35="✓ Có",VLOOKUP(B35,'Hệ Số'!B:C,2,FALSE),0) -> 0 | F35: OAuth2
A36: 28 | B36: Role-based Access | C36: ⚪ Tùy chọn | D36: =IF(AND('📋 Thông Tin'!$B$10="Web Doanh Nghiệp",OR(C36="🟢 Bắt buộc",AND(C36="🟡 Nên có",OR('📋 Thông Tin'!$D$10="Phổ thông (🟢+🟡)",'📋 Thông Tin'!$D$10="Nâng cao (🟢+🟡+⚪)")),AND(C36="⚪ Tùy chọn",'📋 Thông Tin'!$D$10="Nâng cao (🟢+🟡+⚪)"))),"✓ Có","✗ Không") -> ✗ Không | E36: =IF(D36="✓ Có",VLOOKUP(B36,'Hệ Số'!B:C,2,FALSE),0) -> 0 | F36: Phân quyền Admin/User/Staff
A37: 🔔 THÔNG BÁO
A38: 29 | B38: Email notification | C38: 🟡 Nên có | D38: =IF(AND('📋 Thông Tin'!$B$10="Web Doanh Nghiệp",OR(C38="🟢 Bắt buộc",AND(C38="🟡 Nên có",OR('📋 Thông Tin'!$D$10="Phổ thông (🟢+🟡)",'📋 Thông Tin'!$D$10="Nâng cao (🟢+🟡+⚪)")),AND(C38="⚪ Tùy chọn",'📋 Thông Tin'!$D$10="Nâng cao (🟢+🟡+⚪)"))),"✓ Có","✗ Không") -> ✗ Không | E38: =IF(D38="✓ Có",VLOOKUP(B38,'Hệ Số'!B:C,2,FALSE),0) -> 0 | F38: SendGrid
A39: 30 | B39: Admin dashboard notification | C39: 🟡 Nên có | D39: =IF(AND('📋 Thông Tin'!$B$10="Web Doanh Nghiệp",OR(C39="🟢 Bắt buộc",AND(C39="🟡 Nên có",OR('📋 Thông Tin'!$D$10="Phổ thông (🟢+🟡)",'📋 Thông Tin'!$D$10="Nâng cao (🟢+🟡+⚪)")),AND(C39="⚪ Tùy chọn",'📋 Thông Tin'!$D$10="Nâng cao (🟢+🟡+⚪)"))),"✓ Có","✗ Không") -> ✗ Không | E39: =IF(D39="✓ Có",VLOOKUP(B39,'Hệ Số'!B:C,2,FALSE),0) -> 0 | F39: Chuông thông báo
A40: 31 | B40: FCM Push Notification | C40: ⚪ Tùy chọn | D40: =IF(AND('📋 Thông Tin'!$B$10="Web Doanh Nghiệp",OR(C40="🟢 Bắt buộc",AND(C40="🟡 Nên có",OR('📋 Thông Tin'!$D$10="Phổ thông (🟢+🟡)",'📋 Thông Tin'!$D$10="Nâng cao (🟢+🟡+⚪)")),AND(C40="⚪ Tùy chọn",'📋 Thông Tin'!$D$10="Nâng cao (🟢+🟡+⚪)"))),"✓ Có","✗ Không") -> ✗ Không | E40: =IF(D40="✓ Có",VLOOKUP(B40,'Hệ Số'!B:C,2,FALSE),0) -> 0 | F40: Push trình duyệt
A41: 32 | B41: SMS Notification | C41: ⚪ Tùy chọn | D41: =IF(AND('📋 Thông Tin'!$B$10="Web Doanh Nghiệp",OR(C41="🟢 Bắt buộc",AND(C41="🟡 Nên có",OR('📋 Thông Tin'!$D$10="Phổ thông (🟢+🟡)",'📋 Thông Tin'!$D$10="Nâng cao (🟢+🟡+⚪)")),AND(C41="⚪ Tùy chọn",'📋 Thông Tin'!$D$10="Nâng cao (🟢+🟡+⚪)"))),"✓ Có","✗ Không") -> ✗ Không | E41: =IF(D41="✓ Có",VLOOKUP(B41,'Hệ Số'!B:C,2,FALSE),0) -> 0
...

Sheet E-commerce
A1: 📋 E-COMMERCE — BẢNG TÍNH NĂNG
A3: STT | B3: Tính năng | C3: Mức độ | D3: Có / Không | E3: Hệ số | F3: Ghi chú
A4: ⚙️ CORE (Trang cơ bản)
A5: 1 | B5: Homepage (hero + sections + CTA) | C5: 🟢 Bắt buộc | D5: =IF(AND('📋 Thông Tin'!$B$10="E-commerce",OR(C5="🟢 Bắt buộc",AND(C5="🟡 Nên có",OR('📋 Thông Tin'!$D$10="Phổ thông (🟢+🟡)",'📋 Thông Tin'!$D$10="Nâng cao (🟢+🟡+⚪)")),AND(C5="⚪ Tùy chọn",'📋 Thông Tin'!$D$10="Nâng cao (🟢+🟡+⚪)"))),"✓ Có","✗ Không") -> ✗ Không | E5: =IF(D5="✓ Có",VLOOKUP(B5,'Hệ Số'!B:C,2,FALSE),0) -> 0
A6: 2 | B6: About Page | C6: 🟡 Nên có | D6: =IF(AND('📋 Thông Tin'!$B$10="E-commerce",OR(C6="🟢 Bắt buộc",AND(C6="🟡 Nên có",OR('📋 Thông Tin'!$D$10="Phổ thông (🟢+🟡)",'📋 Thông Tin'!$D$10="Nâng cao (🟢+🟡+⚪)")),AND(C6="⚪ Tùy chọn",'📋 Thông Tin'!$D$10="Nâng cao (🟢+🟡+⚪)"))),"✓ Có","✗ Không") -> ✗ Không | E6: =IF(D6="✓ Có",VLOOKUP(B6,'Hệ Số'!B:C,2,FALSE),0) -> 0
A7: 3 | B7: Contact Page (form + map + info) | C7: 🟡 Nên có | D7: =IF(AND('📋 Thông Tin'!$B$10="E-commerce",OR(C7="🟢 Bắt buộc",AND(C7="🟡 Nên có",OR('📋 Thông Tin'!$D$10="Phổ thông (🟢+🟡)",'📋 Thông Tin'!$D$10="Nâng cao (🟢+🟡+⚪)")),AND(C7="⚪ Tùy chọn",'📋 Thông Tin'!$D$10="Nâng cao (🟢+🟡+⚪)"))),"✓ Có","✗ Không") -> ✗ Không | E7: =IF(D7="✓ Có",VLOOKUP(B7,'Hệ Số'!B:C,2,FALSE),0) -> 0
A8: 4 | B8: 404 Page | C8: 🟢 Bắt buộc | D8: =IF(AND('📋 Thông Tin'!$B$10="E-commerce",OR(C8="🟢 Bắt buộc",AND(C8="🟡 Nên có",OR('📋 Thông Tin'!$D$10="Phổ thông (🟢+🟡)",'📋 Thông Tin'!$D$10="Nâng cao (🟢+🟡+⚪)")),AND(C8="⚪ Tùy chọn",'📋 Thông Tin'!$D$10="Nâng cao (🟢+🟡+⚪)"))),"✓ Có","✗ Không") -> ✗ Không | E8: =IF(D8="✓ Có",VLOOKUP(B8,'Hệ Số'!B:C,2,FALSE),0) -> 0
A9: 5 | B9: Footer + Header | C9: 🟢 Bắt buộc | D9: =IF(AND('📋 Thông Tin'!$B$10="E-commerce",OR(C9="🟢 Bắt buộc",AND(C9="🟡 Nên có",OR('📋 Thông Tin'!$D$10="Phổ thông (🟢+🟡)",'📋 Thông Tin'!$D$10="Nâng cao (🟢+🟡+⚪)")),AND(C9="⚪ Tùy chọn",'📋 Thông Tin'!$D$10="Nâng cao (🟢+🟡+⚪)"))),"✓ Có","✗ Không") -> ✗ Không | E9: =IF(D9="✓ Có",VLOOKUP(B9,'Hệ Số'!B:C,2,FALSE),0) -> 0 | F9: Responsive nav, logo
A10: 6 | B10: Form liên hệ (gửi email) | C10: 🟡 Nên có | D10: =IF(AND('📋 Thông Tin'!$B$10="E-commerce",OR(C10="🟢 Bắt buộc",AND(C10="🟡 Nên có",OR('📋 Thông Tin'!$D$10="Phổ thông (🟢+🟡)",'📋 Thông Tin'!$D$10="Nâng cao (🟢+🟡+⚪)")),AND(C10="⚪ Tùy chọn",'📋 Thông Tin'!$D$10="Nâng cao (🟢+🟡+⚪)"))),"✓ Có","✗ Không") -> ✗ Không | E10: =IF(D10="✓ Có",VLOOKUP(B10,'Hệ Số'!B:C,2,FALSE),0) -> 0
A11: 7 | B11: FAB (Floating Action Button) | C11: 🟡 Nên có | D11: =IF(AND('📋 Thông Tin'!$B$10="E-commerce",OR(C11="🟢 Bắt buộc",AND(C11="🟡 Nên có",OR('📋 Thông Tin'!$D$10="Phổ thông (🟢+🟡)",'📋 Thông Tin'!$D$10="Nâng cao (🟢+🟡+⚪)")),AND(C11="⚪ Tùy chọn",'📋 Thông Tin'!$D$10="Nâng cao (🟢+🟡+⚪)"))),"✓ Có","✗ Không") -> ✗ Không | E11: =IF(D11="✓ Có",VLOOKUP(B11,'Hệ Số'!B:C,2,FALSE),0) -> 0 | F11: Nút nổi: gọi/Zalo/Messenger
A12: 8 | B12: Google Maps nhúng | C12: ⚪ Tùy chọn | D12: =IF(AND('📋 Thông Tin'!$B$10="E-commerce",OR(C12="🟢 Bắt buộc",AND(C12="🟡 Nên có",OR('📋 Thông Tin'!$D$10="Phổ thông (🟢+🟡)",'📋 Thông Tin'!$D$10="Nâng cao (🟢+🟡+⚪)")),AND(C12="⚪ Tùy chọn",'📋 Thông Tin'!$D$10="Nâng cao (🟢+🟡+⚪)"))),"✓ Có","✗ Không") -> ✗ Không | E12: =IF(D12="✓ Có",VLOOKUP(B12,'Hệ Số'!B:C,2,FALSE),0) -> 0
A13: 9 | B13: Nút gọi điện / Zalo / Messenger | C13: 🟡 Nên có | D13: =IF(AND('📋 Thông Tin'!$B$10="E-commerce",OR(C13="🟢 Bắt buộc",AND(C13="🟡 Nên có",OR('📋 Thông Tin'!$D$10="Phổ thông (🟢+🟡)",'📋 Thông Tin'!$D$10="Nâng cao (🟢+🟡+⚪)")),AND(C13="⚪ Tùy chọn",'📋 Thông Tin'!$D$10="Nâng cao (🟢+🟡+⚪)"))),"✓ Có","✗ Không") -> ✗ Không | E13: =IF(D13="✓ Có",VLOOKUP(B13,'Hệ Số'!B:C,2,FALSE),0) -> 0 | F13: Nếu không dùng FAB
A14: 📝 NỘI DUNG
A15: 10 | B15: Services/Products List | C15: 🟢 Bắt buộc | D15: =IF(AND('📋 Thông Tin'!$B$10="E-commerce",OR(C15="🟢 Bắt buộc",AND(C15="🟡 Nên có",OR('📋 Thông Tin'!$D$10="Phổ thông (🟢+🟡)",'📋 Thông Tin'!$D$10="Nâng cao (🟢+🟡+⚪)")),AND(C15="⚪ Tùy chọn",'📋 Thông Tin'!$D$10="Nâng cao (🟢+🟡+⚪)"))),"✓ Có","✗ Không") -> ✗ Không | E15: =IF(D15="✓ Có",VLOOKUP(B15,'Hệ Số'!B:C,2,FALSE),0) -> 0 | F15: Danh sách dịch vụ/sản phẩm
A16: 11 | B16: Service/Product Detail | C16: 🟢 Bắt buộc | D16: =IF(AND('📋 Thông Tin'!$B$10="E-commerce",OR(C16="🟢 Bắt buộc",AND(C16="🟡 Nên có",OR('📋 Thông Tin'!$D$10="Phổ thông (🟢+🟡)",'📋 Thông Tin'!$D$10="Nâng cao (🟢+🟡+⚪)")),AND(C16="⚪ Tùy chọn",'📋 Thông Tin'!$D$10="Nâng cao (🟢+🟡+⚪)"))),"✓ Có","✗ Không") -> ✗ Không | E16: =IF(D16="✓ Có",VLOOKUP(B16,'Hệ Số'!B:C,2,FALSE),0) -> 0 | F16: Trang chi tiết
A17: 12 | B17: Portfolio/Gallery Grid | C17: ⚪ Tùy chọn | D17: =IF(AND('📋 Thông Tin'!$B$10="E-commerce",OR(C17="🟢 Bắt buộc",AND(C17="🟡 Nên có",OR('📋 Thông Tin'!$D$10="Phổ thông (🟢+🟡)",'📋 Thông Tin'!$D$10="Nâng cao (🟢+🟡+⚪)")),AND(C17="⚪ Tùy chọn",'📋 Thông Tin'!$D$10="Nâng cao (🟢+🟡+⚪)"))),"✓ Có","✗ Không") -> ✗ Không | E17: =IF(D17="✓ Có",VLOOKUP(B17,'Hệ Số'!B:C,2,FALSE),0) -> 0 | F17: Lưới dự án/album ảnh
A18: 13 | B18: Portfolio Detail | C18: ⚪ Tùy chọn | D18: =IF(AND('📋 Thông Tin'!$B$10="E-commerce",OR(C18="🟢 Bắt buộc",AND(C18="🟡 Nên có",OR('📋 Thông Tin'!$D$10="Phổ thông (🟢+🟡)",'📋 Thông Tin'!$D$10="Nâng cao (🟢+🟡+⚪)")),AND(C18="⚪ Tùy chọn",'📋 Thông Tin'!$D$10="Nâng cao (🟢+🟡+⚪)"))),"✓ Có","✗ Không") -> ✗ Không | E18: =IF(D18="✓ Có",VLOOKUP(B18,'Hệ Số'!B:C,2,FALSE),0) -> 0 | F18: Chi tiết dự án
A19: 14 | B19: Blog List + Detail | C19: ⚪ Tùy chọn | D19: =IF(AND('📋 Thông Tin'!$B$10="E-commerce",OR(C19="🟢 Bắt buộc",AND(C19="🟡 Nên có",OR('📋 Thông Tin'!$D$10="Phổ thông (🟢+🟡)",'📋 Thông Tin'!$D$10="Nâng cao (🟢+🟡+⚪)")),AND(C19="⚪ Tùy chọn",'📋 Thông Tin'!$D$10="Nâng cao (🟢+🟡+⚪)"))),"✓ Có","✗ Không") -> ✗ Không | E19: =IF(D19="✓ Có",VLOOKUP(B19,'Hệ Số'!B:C,2,FALSE),0) -> 0 | F19: Bài viết + phân loại + tag
A20: 15 | B20: FAQ Page | C20: 🟡 Nên có | D20: =IF(AND('📋 Thông Tin'!$B$10="E-commerce",OR(C20="🟢 Bắt buộc",AND(C20="🟡 Nên có",OR('📋 Thông Tin'!$D$10="Phổ thông (🟢+🟡)",'📋 Thông Tin'!$D$10="Nâng cao (🟢+🟡+⚪)")),AND(C20="⚪ Tùy chọn",'📋 Thông Tin'!$D$10="Nâng cao (🟢+🟡+⚪)"))),"✓ Có","✗ Không") -> ✗ Không | E20: =IF(D20="✓ Có",VLOOKUP(B20,'Hệ Số'!B:C,2,FALSE),0) -> 0 | F20: Accordion Q&A
A21: 16 | B21: Testimonials Section | C21: 🟡 Nên có | D21: =IF(AND('📋 Thông Tin'!$B$10="E-commerce",OR(C21="🟢 Bắt buộc",AND(C21="🟡 Nên có",OR('📋 Thông Tin'!$D$10="Phổ thông (🟢+🟡)",'📋 Thông Tin'!$D$10="Nâng cao (🟢+🟡+⚪)")),AND(C21="⚪ Tùy chọn",'📋 Thông Tin'!$D$10="Nâng cao (🟢+🟡+⚪)"))),"✓ Có","✗ Không") -> ✗ Không | E21: =IF(D21="✓ Có",VLOOKUP(B21,'Hệ Số'!B:C,2,FALSE),0) -> 0 | F21: Đánh giá khách hàng
A22: 17 | B22: Video nhúng (YouTube, Vimeo) | C22: ⚪ Tùy chọn | D22: =IF(AND('📋 Thông Tin'!$B$10="E-commerce",OR(C22="🟢 Bắt buộc",AND(C22="🟡 Nên có",OR('📋 Thông Tin'!$D$10="Phổ thông (🟢+🟡)",'📋 Thông Tin'!$D$10="Nâng cao (🟢+🟡+⚪)")),AND(C22="⚪ Tùy chọn",'📋 Thông Tin'!$D$10="Nâng cao (🟢+🟡+⚪)"))),"✓ Có","✗ Không") -> ✗ Không | E22: =IF(D22="✓ Có",VLOOKUP(B22,'Hệ Số'!B:C,2,FALSE),0) -> 0
A23: 18 | B23: Banner / Slider quản lý | C23: 🟡 Nên có | D23: =IF(AND('📋 Thông Tin'!$B$10="E-commerce",OR(C23="🟢 Bắt buộc",AND(C23="🟡 Nên có",OR('📋 Thông Tin'!$D$10="Phổ thông (🟢+🟡)",'📋 Thông Tin'!$D$10="Nâng cao (🟢+🟡+⚪)")),AND(C23="⚪ Tùy chọn",'📋 Thông Tin'!$D$10="Nâng cao (🟢+🟡+⚪)"))),"✓ Có","✗ Không") -> ✗ Không | E23: =IF(D23="✓ Có",VLOOKUP(B23,'Hệ Số'!B:C,2,FALSE),0) -> 0 | F23: Admin quản lý banner
A24: 19 | B24: Đánh giá / Review sản phẩm | C24: 🟡 Nên có | D24: =IF(AND('📋 Thông Tin'!$B$10="E-commerce",OR(C24="🟢 Bắt buộc",AND(C24="🟡 Nên có",OR('📋 Thông Tin'!$D$10="Phổ thông (🟢+🟡)",'📋 Thông Tin'!$D$10="Nâng cao (🟢+🟡+⚪)")),AND(C24="⚪ Tùy chọn",'📋 Thông Tin'!$D$10="Nâng cao (🟢+🟡+⚪)"))),"✓ Có","✗ Không") -> ✗ Không | E24: =IF(D24="✓ Có",VLOOKUP(B24,'Hệ Số'!B:C,2,FALSE),0) -> 0 | F24: Rating + comment
A25: 🛒 BOOKING & THƯƠNG MẠI
A26: 20 | B26: Shopping Cart | C26: 🟢 Bắt buộc | D26: =IF(AND('📋 Thông Tin'!$B$10="E-commerce",OR(C26="🟢 Bắt buộc",AND(C26="🟡 Nên có",OR('📋 Thông Tin'!$D$10="Phổ thông (🟢+🟡)",'📋 Thông Tin'!$D$10="Nâng cao (🟢+🟡+⚪)")),AND(C26="⚪ Tùy chọn",'📋 Thông Tin'!$D$10="Nâng cao (🟢+🟡+⚪)"))),"✓ Có","✗ Không") -> ✗ Không | E26: =IF(D26="✓ Có",VLOOKUP(B26,'Hệ Số'!B:C,2,FALSE),0) -> 0 | F26: Giỏ hàng
A27: 21 | B27: Checkout + Payment (Stripe/VNPay) | C27: 🟢 Bắt buộc | D27: =IF(AND('📋 Thông Tin'!$B$10="E-commerce",OR(C27="🟢 Bắt buộc",AND(C27="🟡 Nên có",OR('📋 Thông Tin'!$D$10="Phổ thông (🟢+🟡)",'📋 Thông Tin'!$D$10="Nâng cao (🟢+🟡+⚪)")),AND(C27="⚪ Tùy chọn",'📋 Thông Tin'!$D$10="Nâng cao (🟢+🟡+⚪)"))),"✓ Có","✗ Không") -> ✗ Không | E27: =IF(D27="✓ Có",VLOOKUP(B27,'Hệ Số'!B:C,2,FALSE),0) -> 0 | F27: Thanh toán online
A28: 22 | B28: Order Tracking | C28: 🟡 Nên có | D28: =IF(AND('📋 Thông Tin'!$B$10="E-commerce",OR(C28="🟢 Bắt buộc",AND(C28="🟡 Nên có",OR('📋 Thông Tin'!$D$10="Phổ thông (🟢+🟡)",'📋 Thông Tin'!$D$10="Nâng cao (🟢+🟡+⚪)")),AND(C28="⚪ Tùy chọn",'📋 Thông Tin'!$D$10="Nâng cao (🟢+🟡+⚪)"))),"✓ Có","✗ Không") -> ✗ Không | E28: =IF(D28="✓ Có",VLOOKUP(B28,'Hệ Số'!B:C,2,FALSE),0) -> 0 | F28: Theo dõi đơn hàng
A29: 23 | B29: Mã giảm giá / Voucher | C29: 🟡 Nên có | D29: =IF(AND('📋 Thông Tin'!$B$10="E-commerce",OR(C29="🟢 Bắt buộc",AND(C29="🟡 Nên có",OR('📋 Thông Tin'!$D$10="Phổ thông (🟢+🟡)",'📋 Thông Tin'!$D$10="Nâng cao (🟢+🟡+⚪)")),AND(C29="⚪ Tùy chọn",'📋 Thông Tin'!$D$10="Nâng cao (🟢+🟡+⚪)"))),"✓ Có","✗ Không") -> ✗ Không | E29: =IF(D29="✓ Có",VLOOKUP(B29,'Hệ Số'!B:C,2,FALSE),0) -> 0 | F29: Coupon system
A30: 📊 ADMIN & QUẢN TRỊ
A31: 24 | B31: Dashboard Admin (CRUD cơ bản) | C31: 🟡 Nên có | D31: =IF(AND('📋 Thông Tin'!$B$10="E-commerce",OR(C31="🟢 Bắt buộc",AND(C31="🟡 Nên có",OR('📋 Thông Tin'!$D$10="Phổ thông (🟢+🟡)",'📋 Thông Tin'!$D$10="Nâng cao (🟢+🟡+⚪)")),AND(C31="⚪ Tùy chọn",'📋 Thông Tin'!$D$10="Nâng cao (🟢+🟡+⚪)"))),"✓ Có","✗ Không") -> ✗ Không | E31: =IF(D31="✓ Có",VLOOKUP(B31,'Hệ Số'!B:C,2,FALSE),0) -> 0 | F31: Quản lý dữ liệu
A32: 25 | B32: Dashboard Full (CRUD + analytics) | C32: ⚪ Tùy chọn | D32: =IF(AND('📋 Thông Tin'!$B$10="E-commerce",OR(C32="🟢 Bắt buộc",AND(C32="🟡 Nên có",OR('📋 Thông Tin'!$D$10="Phổ thông (🟢+🟡)",'📋 Thông Tin'!$D$10="Nâng cao (🟢+🟡+⚪)")),AND(C32="⚪ Tùy chọn",'📋 Thông Tin'!$D$10="Nâng cao (🟢+🟡+⚪)"))),"✓ Có","✗ Không") -> ✗ Không | E32: =IF(D32="✓ Có",VLOOKUP(B32,'Hệ Số'!B:C,2,FALSE),0) -> 0 | F32: Charts, KPIs, reports
A33: 26 | B33: Site Config Editor | C33: ⚪ Tùy chọn | D33: =IF(AND('📋 Thông Tin'!$B$10="E-commerce",OR(C33="🟢 Bắt buộc",AND(C33="🟡 Nên có",OR('📋 Thông Tin'!$D$10="Phổ thông (🟢+🟡)",'📋 Thông Tin'!$D$10="Nâng cao (🟢+🟡+⚪)")),AND(C33="⚪ Tùy chọn",'📋 Thông Tin'!$D$10="Nâng cao (🟢+🟡+⚪)"))),"✓ Có","✗ Không") -> ✗ Không | E33: =IF(D33="✓ Có",VLOOKUP(B33,'Hệ Số'!B:C,2,FALSE),0) -> 0 | F33: Cài đặt hệ thống
A34: 27 | B34: User Management | C34: 🟡 Nên có | D34: =IF(AND('📋 Thông Tin'!$B$10="E-commerce",OR(C34="🟢 Bắt buộc",AND(C34="🟡 Nên có",OR('📋 Thông Tin'!$D$10="Phổ thông (🟢+🟡)",'📋 Thông Tin'!$D$10="Nâng cao (🟢+🟡+⚪)")),AND(C34="⚪ Tùy chọn",'📋 Thông Tin'!$D$10="Nâng cao (🟢+🟡+⚪)"))),"✓ Có","✗ Không") -> ✗ Không | E34: =IF(D34="✓ Có",VLOOKUP(B34,'Hệ Số'!B:C,2,FALSE),0) -> 0 | F34: Quản lý tài khoản
A35: 28 | B35: Xuất báo cáo (Excel, PDF) | C35: 🟡 Nên có | D35: =IF(AND('📋 Thông Tin'!$B$10="E-commerce",OR(C35="🟢 Bắt buộc",AND(C35="🟡 Nên có",OR('📋 Thông Tin'!$D$10="Phổ thông (🟢+🟡)",'📋 Thông Tin'!$D$10="Nâng cao (🟢+🟡+⚪)")),AND(C35="⚪ Tùy chọn",'📋 Thông Tin'!$D$10="Nâng cao (🟢+🟡+⚪)"))),"✓ Có","✗ Không") -> ✗ Không | E35: =IF(D35="✓ Có",VLOOKUP(B35,'Hệ Số'!B:C,2,FALSE),0) -> 0 | F35: Export reports
A36: 🔐 TÀI KHOẢN & BẢO MẬT
A37: 29 | B37: Login/Register (Firebase Auth) | C37: 🟢 Bắt buộc | D37: =IF(AND('📋 Thông Tin'!$B$10="E-commerce",OR(C37="🟢 Bắt buộc",AND(C37="🟡 Nên có",OR('📋 Thông Tin'!$D$10="Phổ thông (🟢+🟡)",'📋 Thông Tin'!$D$10="Nâng cao (🟢+🟡+⚪)")),AND(C37="⚪ Tùy chọn",'📋 Thông Tin'!$D$10="Nâng cao (🟢+🟡+⚪)"))),"✓ Có","✗ Không") -> ✗ Không | E37: =IF(D37="✓ Có",VLOOKUP(B37,'Hệ Số'!B:C,2,FALSE),0) -> 0
A38: 30 | B38: Social Login (Google/Facebook) | C38: 🟡 Nên có | D38: =IF(AND('📋 Thông Tin'!$B$10="E-commerce",OR(C38="🟢 Bắt buộc",AND(C38="🟡 Nên có",OR('📋 Thông Tin'!$D$10="Phổ thông (🟢+🟡)",'📋 Thông Tin'!$D$10="Nâng cao (🟢+🟡+⚪)")),AND(C38="⚪ Tùy chọn",'📋 Thông Tin'!$D$10="Nâng cao (🟢+🟡+⚪)"))),"✓ Có","✗ Không") -> ✗ Không | E38: =IF(D38="✓ Có",VLOOKUP(B38,'Hệ Số'!B:C,2,FALSE),0) -> 0 | F38: OAuth2
A39: 31 | B39: Role-based Access | C39: 🟡 Nên có | D39: =IF(AND('📋 Thông Tin'!$B$10="E-commerce",OR(C39="🟢 Bắt buộc",AND(C39="🟡 Nên có",OR('📋 Thông Tin'!$D$10="Phổ thông (🟢+🟡)",'📋 Thông Tin'!$D$10="Nâng cao (🟢+🟡+⚪)")),AND(C39="⚪ Tùy chọn",'📋 Thông Tin'!$D$10="Nâng cao (🟢+🟡+⚪)"))),"✓ Có","✗ Không") -> ✗ Không | E39: =IF(D39="✓ Có",VLOOKUP(B39,'Hệ Số'!B:C,2,FALSE),0) -> 0 | F39: Phân quyền Admin/User/Staff
A40: 🔔 THÔNG BÁO
A41: 32 | B41: Email notification | C41: 🟡 Nên có | D41: =IF(AND('📋 Thông Tin'!$B$10="E-commerce",OR(C41="🟢 Bắt buộc",AND(C41="🟡 Nên có",OR('📋 Thông Tin'!$D$10="Phổ thông (🟢+🟡)",'📋 Thông Tin'!$D$10="Nâng cao (🟢+🟡+⚪)")),AND(C41="⚪ Tùy chọn",'📋 Thông Tin'!$D$10="Nâng cao (🟢+🟡+⚪)"))),"✓ Có","✗ Không") -> ✗ Không | E41: =IF(D41="✓ Có",VLOOKUP(B41,'Hệ Số'!B:C,2,FALSE),0) -> 0 | F41: SendGrid
...

Sheet Web App
A1: 📋 WEB APP — BẢNG TÍNH NĂNG
A3: STT | B3: Tính năng | C3: Mức độ | D3: Có / Không | E3: Hệ số | F3: Ghi chú
A4: ⚙️ CORE (Trang cơ bản)
A5: 1 | B5: Homepage (hero + sections + CTA) | C5: 🟢 Bắt buộc | D5: =IF(AND('📋 Thông Tin'!$B$10="Web App",OR(C5="🟢 Bắt buộc",AND(C5="🟡 Nên có",OR('📋 Thông Tin'!$D$10="Phổ thông (🟢+🟡)",'📋 Thông Tin'!$D$10="Nâng cao (🟢+🟡+⚪)")),AND(C5="⚪ Tùy chọn",'📋 Thông Tin'!$D$10="Nâng cao (🟢+🟡+⚪)"))),"✓ Có","✗ Không") -> ✗ Không | E5: =IF(D5="✓ Có",VLOOKUP(B5,'Hệ Số'!B:C,2,FALSE),0) -> 0
A6: 2 | B6: About Page | C6: ⚪ Tùy chọn | D6: =IF(AND('📋 Thông Tin'!$B$10="Web App",OR(C6="🟢 Bắt buộc",AND(C6="🟡 Nên có",OR('📋 Thông Tin'!$D$10="Phổ thông (🟢+🟡)",'📋 Thông Tin'!$D$10="Nâng cao (🟢+🟡+⚪)")),AND(C6="⚪ Tùy chọn",'📋 Thông Tin'!$D$10="Nâng cao (🟢+🟡+⚪)"))),"✓ Có","✗ Không") -> ✗ Không | E6: =IF(D6="✓ Có",VLOOKUP(B6,'Hệ Số'!B:C,2,FALSE),0) -> 0
A7: 3 | B7: Contact Page (form + map + info) | C7: ⚪ Tùy chọn | D7: =IF(AND('📋 Thông Tin'!$B$10="Web App",OR(C7="🟢 Bắt buộc",AND(C7="🟡 Nên có",OR('📋 Thông Tin'!$D$10="Phổ thông (🟢+🟡)",'📋 Thông Tin'!$D$10="Nâng cao (🟢+🟡+⚪)")),AND(C7="⚪ Tùy chọn",'📋 Thông Tin'!$D$10="Nâng cao (🟢+🟡+⚪)"))),"✓ Có","✗ Không") -> ✗ Không | E7: =IF(D7="✓ Có",VLOOKUP(B7,'Hệ Số'!B:C,2,FALSE),0) -> 0
A8: 4 | B8: 404 Page | C8: 🟢 Bắt buộc | D8: =IF(AND('📋 Thông Tin'!$B$10="Web App",OR(C8="🟢 Bắt buộc",AND(C8="🟡 Nên có",OR('📋 Thông Tin'!$D$10="Phổ thông (🟢+🟡)",'📋 Thông Tin'!$D$10="Nâng cao (🟢+🟡+⚪)")),AND(C8="⚪ Tùy chọn",'📋 Thông Tin'!$D$10="Nâng cao (🟢+🟡+⚪)"))),"✓ Có","✗ Không") -> ✗ Không | E8: =IF(D8="✓ Có",VLOOKUP(B8,'Hệ Số'!B:C,2,FALSE),0) -> 0
A9: 5 | B9: Footer + Header | C9: 🟢 Bắt buộc | D9: =IF(AND('📋 Thông Tin'!$B$10="Web App",OR(C9="🟢 Bắt buộc",AND(C9="🟡 Nên có",OR('📋 Thông Tin'!$D$10="Phổ thông (🟢+🟡)",'📋 Thông Tin'!$D$10="Nâng cao (🟢+🟡+⚪)")),AND(C9="⚪ Tùy chọn",'📋 Thông Tin'!$D$10="Nâng cao (🟢+🟡+⚪)"))),"✓ Có","✗ Không") -> ✗ Không | E9: =IF(D9="✓ Có",VLOOKUP(B9,'Hệ Số'!B:C,2,FALSE),0) -> 0 | F9: Responsive nav, logo
A10: 6 | B10: Form liên hệ (gửi email) | C10: ⚪ Tùy chọn | D10: =IF(AND('📋 Thông Tin'!$B$10="Web App",OR(C10="🟢 Bắt buộc",AND(C10="🟡 Nên có",OR('📋 Thông Tin'!$D$10="Phổ thông (🟢+🟡)",'📋 Thông Tin'!$D$10="Nâng cao (🟢+🟡+⚪)")),AND(C10="⚪ Tùy chọn",'📋 Thông Tin'!$D$10="Nâng cao (🟢+🟡+⚪)"))),"✓ Có","✗ Không") -> ✗ Không | E10: =IF(D10="✓ Có",VLOOKUP(B10,'Hệ Số'!B:C,2,FALSE),0) -> 0
A11: 7 | B11: FAB (Floating Action Button) | C11: ⚪ Tùy chọn | D11: =IF(AND('📋 Thông Tin'!$B$10="Web App",OR(C11="🟢 Bắt buộc",AND(C11="🟡 Nên có",OR('📋 Thông Tin'!$D$10="Phổ thông (🟢+🟡)",'📋 Thông Tin'!$D$10="Nâng cao (🟢+🟡+⚪)")),AND(C11="⚪ Tùy chọn",'📋 Thông Tin'!$D$10="Nâng cao (🟢+🟡+⚪)"))),"✓ Có","✗ Không") -> ✗ Không | E11: =IF(D11="✓ Có",VLOOKUP(B11,'Hệ Số'!B:C,2,FALSE),0) -> 0 | F11: Nút nổi: gọi/Zalo/Messenger
A12: 8 | B12: Nút gọi điện / Zalo / Messenger | C12: ⚪ Tùy chọn | D12: =IF(AND('📋 Thông Tin'!$B$10="Web App",OR(C12="🟢 Bắt buộc",AND(C12="🟡 Nên có",OR('📋 Thông Tin'!$D$10="Phổ thông (🟢+🟡)",'📋 Thông Tin'!$D$10="Nâng cao (🟢+🟡+⚪)")),AND(C12="⚪ Tùy chọn",'📋 Thông Tin'!$D$10="Nâng cao (🟢+🟡+⚪)"))),"✓ Có","✗ Không") -> ✗ Không | E12: =IF(D12="✓ Có",VLOOKUP(B12,'Hệ Số'!B:C,2,FALSE),0) -> 0 | F12: Nếu không dùng FAB
A13: 📝 NỘI DUNG
A14: 9 | B14: Portfolio/Gallery Grid | C14: ⚪ Tùy chọn | D14: =IF(AND('📋 Thông Tin'!$B$10="Web App",OR(C14="🟢 Bắt buộc",AND(C14="🟡 Nên có",OR('📋 Thông Tin'!$D$10="Phổ thông (🟢+🟡)",'📋 Thông Tin'!$D$10="Nâng cao (🟢+🟡+⚪)")),AND(C14="⚪ Tùy chọn",'📋 Thông Tin'!$D$10="Nâng cao (🟢+🟡+⚪)"))),"✓ Có","✗ Không") -> ✗ Không | E14: =IF(D14="✓ Có",VLOOKUP(B14,'Hệ Số'!B:C,2,FALSE),0) -> 0 | F14: Lưới dự án/album ảnh
A15: 10 | B15: Portfolio Detail | C15: ⚪ Tùy chọn | D15: =IF(AND('📋 Thông Tin'!$B$10="Web App",OR(C15="🟢 Bắt buộc",AND(C15="🟡 Nên có",OR('📋 Thông Tin'!$D$10="Phổ thông (🟢+🟡)",'📋 Thông Tin'!$D$10="Nâng cao (🟢+🟡+⚪)")),AND(C15="⚪ Tùy chọn",'📋 Thông Tin'!$D$10="Nâng cao (🟢+🟡+⚪)"))),"✓ Có","✗ Không") -> ✗ Không | E15: =IF(D15="✓ Có",VLOOKUP(B15,'Hệ Số'!B:C,2,FALSE),0) -> 0 | F15: Chi tiết dự án
A16: 11 | B16: Blog List + Detail | C16: ⚪ Tùy chọn | D16: =IF(AND('📋 Thông Tin'!$B$10="Web App",OR(C16="🟢 Bắt buộc",AND(C16="🟡 Nên có",OR('📋 Thông Tin'!$D$10="Phổ thông (🟢+🟡)",'📋 Thông Tin'!$D$10="Nâng cao (🟢+🟡+⚪)")),AND(C16="⚪ Tùy chọn",'📋 Thông Tin'!$D$10="Nâng cao (🟢+🟡+⚪)"))),"✓ Có","✗ Không") -> ✗ Không | E16: =IF(D16="✓ Có",VLOOKUP(B16,'Hệ Số'!B:C,2,FALSE),0) -> 0 | F16: Bài viết + phân loại + tag
A17: 12 | B17: FAQ Page | C17: ⚪ Tùy chọn | D17: =IF(AND('📋 Thông Tin'!$B$10="Web App",OR(C17="🟢 Bắt buộc",AND(C17="🟡 Nên có",OR('📋 Thông Tin'!$D$10="Phổ thông (🟢+🟡)",'📋 Thông Tin'!$D$10="Nâng cao (🟢+🟡+⚪)")),AND(C17="⚪ Tùy chọn",'📋 Thông Tin'!$D$10="Nâng cao (🟢+🟡+⚪)"))),"✓ Có","✗ Không") -> ✗ Không | E17: =IF(D17="✓ Có",VLOOKUP(B17,'Hệ Số'!B:C,2,FALSE),0) -> 0 | F17: Accordion Q&A
A18: 13 | B18: Testimonials Section | C18: ⚪ Tùy chọn | D18: =IF(AND('📋 Thông Tin'!$B$10="Web App",OR(C18="🟢 Bắt buộc",AND(C18="🟡 Nên có",OR('📋 Thông Tin'!$D$10="Phổ thông (🟢+🟡)",'📋 Thông Tin'!$D$10="Nâng cao (🟢+🟡+⚪)")),AND(C18="⚪ Tùy chọn",'📋 Thông Tin'!$D$10="Nâng cao (🟢+🟡+⚪)"))),"✓ Có","✗ Không") -> ✗ Không | E18: =IF(D18="✓ Có",VLOOKUP(B18,'Hệ Số'!B:C,2,FALSE),0) -> 0 | F18: Đánh giá khách hàng
